Workbook

Sheet 月度数据统计
A1: 每月调单数量（以调单类型分类） | G1: 每月调单数量（以业务线分类） | L1: 时间 | M1: 每月调单总数 | N1: 每月环比增长
A2: 时间 | B2: Recall | C2: LER | D2: Retrieval Request | E2: Personal information | F2: 每月总和 | G2: 时间 | H2: 电商 | I2: B2B | J2: 服贸汇兑 | K2: 每月总和 | L2: 2024年12月 | M2: 64 | N2: 0
A3: 2025年1月 | B3: =COUNTIFS(Recall!C:C,A3) -> 9 | C3: =COUNTIFS(警方协查!C:C,A3) -> 6 | D3: =COUNTIFS(KYC调单!C:C,A3,KYC调单!M:M,"=Retrieval Request")+COUNTIFS(单笔交易!C:C,A3,单笔交易!Q:Q,"=Retrieval Request")+COUNTIF(账户调查!C:C,A3)+COUNTIF(结汇!C:C,A3) -> 17 | E3: =COUNTIFS(KYC调单!C:C,A3,KYC调单!M:M,"Personal Information")+COUNTIFS(单笔交易!C:C,A3,单笔交易!Q:Q,"Personal Information") -> 25 | F3: =SUM(B3:E3) -> 57 | G3: 2025年1月 | H3: =COUNTIFS(KYC调单!C:C,G3,KYC调单!D:D,$H$2)+COUNTIFS(单笔交易!C:C,G3,单笔交易!D:D,$H$2)+COUNTIFS(账户调查!C:C,G3,账户调查!D:D,$H$2)+COUNTIFS(警方协查!C:C,G3,警方协查!F:F,$H$2)+COUNTIFS(Recall!C:C,G3,Recall!F:F,$H$2) -> 38 | I3: =COUNTIFS(KYC调单!C:C,G3,KYC调单!D:D,$I$2)+COUNTIFS(单笔交易!C:C,G3,单笔交易!D:D,$I$2)+COUNTIFS(账户调查!C:C,G3,账户调查!D:D,$I$2)+COUNTIFS(警方协查!C:C,G3,警方协查!F:F,$I$2)+COUNTIFS(Recall!C:C,G3,Recall!F:F,$I$2) -> 12 | J3: =COUNTIFS(KYC调单!C:C,G3,KYC调单!D:D,$J$2)+COUNTIFS(单笔交易!C:C,G3,单笔交易!D:D,$J$2)+COUNTIFS(账户调查!C:C,G3,账户调查!D:D,$J$2)+COUNTIF(结汇!C:C,G3)+COUNTIFS(警方协查!C:C,G3,警方协查!F:F,$J$2)+COUNTIFS(Recall!C:C,G3,Recall!F:F,$J$2) -> 7 | K3: =SUM(H3:J3) -> 57 | L3: 2025年1月 | M3: =F3 -> 57 | N3: =(M3-M2)/M2 -> -0.109375
A4: 2025年2月 | B4: =COUNTIFS(Recall!C:C,A4) -> 12 | C4: =COUNTIFS(警方协查!C:C,A4) -> 0 | D4: =COUNTIFS(KYC调单!C:C,A4,KYC调单!M:M,"=Retrieval Request")+COUNTIFS(单笔交易!C:C,A4,单笔交易!Q:Q,"=Retrieval Request")+COUNTIF(账户调查!C:C,A4)+COUNTIF(结汇!C:C,A4) -> 11 | E4: =COUNTIFS(KYC调单!C:C,A4,KYC调单!M:M,"Personal Information")+COUNTIFS(单笔交易!C:C,A4,单笔交易!Q:Q,"Personal Information") -> 19 | F4: =SUM(B4:E4) -> 42 | G4: 2025年2月 | H4: =COUNTIFS(KYC调单!C:C,G4,KYC调单!D:D,$H$2)+COUNTIFS(单笔交易!C:C,G4,单笔交易!D:D,$H$2)+COUNTIFS(账户调查!C:C,G4,账户调查!D:D,$H$2)+COUNTIFS(警方协查!C:C,G4,警方协查!F:F,$H$2)+COUNTIFS(Recall!C:C,G4,Recall!F:F,$H$2) -> 21 | I4: =COUNTIFS(KYC调单!C:C,G4,KYC调单!D:D,$I$2)+COUNTIFS(单笔交易!C:C,G4,单笔交易!D:D,$I$2)+COUNTIFS(账户调查!C:C,G4,账户调查!D:D,$I$2)+COUNTIFS(警方协查!C:C,G4,警方协查!F:F,$I$2)+COUNTIFS(Recall!C:C,G4,Recall!F:F,$I$2) -> 9 | J4: =COUNTIFS(KYC调单!C:C,G4,KYC调单!D:D,$J$2)+COUNTIFS(单笔交易!C:C,G4,单笔交易!D:D,$J$2)+COUNTIFS(账户调查!C:C,G4,账户调查!D:D,$J$2)+COUNTIF(结汇!C:C,G4)+COUNTIFS(警方协查!C:C,G4,警方协查!F:F,$J$2)+COUNTIFS(Recall!C:C,G4,Recall!F:F,$J$2) -> 12 | K4: =SUM(H4:J4) -> 42 | L4: 2025年2月 | M4: =F4 -> 42 | N4: =(M4-M3)/M3 -> -0.26315789
A5: 2025年3月 | B5: =COUNTIFS(Recall!C:C,A5) -> 15 | C5: =COUNTIFS(警方协查!C:C,A5) -> 2 | D5: =COUNTIFS(KYC调单!C:C,A5,KYC调单!M:M,"=Retrieval Request")+COUNTIFS(单笔交易!C:C,A5,单笔交易!Q:Q,"=Retrieval Request")+COUNTIF(账户调查!C:C,A5)+COUNTIF(结汇!C:C,A5) -> 22 | E5: =COUNTIFS(KYC调单!C:C,A5,KYC调单!M:M,"Personal Information")+COUNTIFS(单笔交易!C:C,A5,单笔交易!Q:Q,"Personal Information") -> 21 | F5: =SUM(B5:E5) -> 60 | G5: 2025年3月 | H5: =COUNTIFS(KYC调单!C:C,G5,KYC调单!D:D,$H$2)+COUNTIFS(单笔交易!C:C,G5,单笔交易!D:D,$H$2)+COUNTIFS(账户调查!C:C,G5,账户调查!D:D,$H$2)+COUNTIFS(警方协查!C:C,G5,警方协查!F:F,$H$2)+COUNTIFS(Recall!C:C,G5,Recall!F:F,$H$2) -> 28 | I5: =COUNTIFS(KYC调单!C:C,G5,KYC调单!D:D,$I$2)+COUNTIFS(单笔交易!C:C,G5,单笔交易!D:D,$I$2)+COUNTIFS(账户调查!C:C,G5,账户调查!D:D,$I$2)+COUNTIFS(警方协查!C:C,G5,警方协查!F:F,$I$2)+COUNTIFS(Recall!C:C,G5,Recall!F:F,$I$2) -> 9 | J5: =COUNTIFS(KYC调单!C:C,G5,KYC调单!D:D,$J$2)+COUNTIFS(单笔交易!C:C,G5,单笔交易!D:D,$J$2)+COUNTIFS(账户调查!C:C,G5,账户调查!D:D,$J$2)+COUNTIF(结汇!C:C,G5)+COUNTIFS(警方协查!C:C,G5,警方协查!F:F,$J$2)+COUNTIFS(Recall!C:C,G5,Recall!F:F,$J$2) -> 23 | K5: =SUM(H5:J5) -> 60 | L5: 2025年3月 | M5: =F5 -> 60 | N5: =(M5-M4)/M4 -> 0.42857143
A6: 2025年4月 | B6: =COUNTIFS(Recall!C:C,A6) -> 2 | C6: =COUNTIFS(警方协查!C:C,A6) -> 5 | D6: =COUNTIFS(KYC调单!C:C,A6,KYC调单!M:M,"=Retrieval Request")+COUNTIFS(单笔交易!C:C,A6,单笔交易!Q:Q,"=Retrieval Request")+COUNTIF(账户调查!C:C,A6)+COUNTIF(结汇!C:C,A6) -> 20 | E6: =COUNTIFS(KYC调单!C:C,A6,KYC调单!M:M,"Personal Information")+COUNTIFS(单笔交易!C:C,A6,单笔交易!Q:Q,"Personal Information") -> 29 | F6: =SUM(B6:E6) -> 56 | G6: 2025年4月 | H6: =COUNTIFS(KYC调单!C:C,G6,KYC调单!D:D,$H$2)+COUNTIFS(单笔交易!C:C,G6,单笔交易!D:D,$H$2)+COUNTIFS(账户调查!C:C,G6,账户调查!D:D,$H$2)+COUNTIFS(警方协查!C:C,G6,警方协查!F:F,$H$2)+COUNTIFS(Recall!C:C,G6,Recall!F:F,$H$2) -> 22 | I6: =COUNTIFS(KYC调单!C:C,G6,KYC调单!D:D,$I$2)+COUNTIFS(单笔交易!C:C,G6,单笔交易!D:D,$I$2)+COUNTIFS(账户调查!C:C,G6,账户调查!D:D,$I$2)+COUNTIFS(警方协查!C:C,G6,警方协查!F:F,$I$2)+COUNTIFS(Recall!C:C,G6,Recall!F:F,$I$2) -> 14 | J6: =COUNTIFS(KYC调单!C:C,G6,KYC调单!D:D,$J$2)+COUNTIFS(单笔交易!C:C,G6,单笔交易!D:D,$J$2)+COUNTIFS(账户调查!C:C,G6,账户调查!D:D,$J$2)+COUNTIF(结汇!C:C,G6)+COUNTIFS(警方协查!C:C,G6,警方协查!F:F,$J$2)+COUNTIFS(Recall!C:C,G6,Recall!F:F,$J$2) -> 20 | K6: =SUM(H6:J6) -> 56 | L6: 2025年4月 | M6: =F6 -> 56 | N6: =(M6-M5)/M5 -> -0.066666667
A7: 2025年5月 | B7: =COUNTIFS(Recall!C:C,A7) -> 11 | C7: =COUNTIFS(警方协查!C:C,A7) -> 1 | D7: =COUNTIFS(KYC调单!C:C,A7,KYC调单!M:M,"=Retrieval Request")+COUNTIFS(单笔交易!C:C,A7,单笔交易!Q:Q,"=Retrieval Request")+COUNTIF(账户调查!C:C,A7)+COUNTIF(结汇!C:C,A7) -> 22 | E7: =COUNTIFS(KYC调单!C:C,A7,KYC调单!M:M,"Personal Information")+COUNTIFS(单笔交易!C:C,A7,单笔交易!Q:Q,"Personal Information") -> 32 | F7: =SUM(B7:E7) -> 66 | G7: 2025年5月 | H7: =COUNTIFS(KYC调单!C:C,G7,KYC调单!D:D,$H$2)+COUNTIFS(单笔交易!C:C,G7,单笔交易!D:D,$H$2)+COUNTIFS(账户调查!C:C,G7,账户调查!D:D,$H$2)+COUNTIFS(警方协查!C:C,G7,警方协查!F:F,$H$2)+COUNTIFS(Recall!C:C,G7,Recall!F:F,$H$2) -> 25 | I7: =COUNTIFS(KYC调单!C:C,G7,KYC调单!D:D,$I$2)+COUNTIFS(单笔交易!C:C,G7,单笔交易!D:D,$I$2)+COUNTIFS(账户调查!C:C,G7,账户调查!D:D,$I$2)+COUNTIFS(警方协查!C:C,G7,警方协查!F:F,$I$2)+COUNTIFS(Recall!C:C,G7,Recall!F:F,$I$2) -> 20 | J7: =COUNTIFS(KYC调单!C:C,G7,KYC调单!D:D,$J$2)+COUNTIFS(单笔交易!C:C,G7,单笔交易!D:D,$J$2)+COUNTIFS(账户调查!C:C,G7,账户调查!D:D,$J$2)+COUNTIF(结汇!C:C,G7)+COUNTIFS(警方协查!C:C,G7,警方协查!F:F,$J$2)+COUNTIFS(Recall!C:C,G7,Recall!F:F,$J$2) -> 21 | K7: =SUM(H7:J7) -> 66 | L7: 2025年5月 | M7: =F7 -> 66 | N7: =(M7-M6)/M6 -> 0.17857143
A8: 2025年6月 | B8: =COUNTIFS(Recall!C:C,A8) -> 15 | C8: =COUNTIFS(警方协查!C:C,A8) -> 7 | D8: =COUNTIFS(KYC调单!C:C,A8,KYC调单!M:M,"=Retrieval Request")+COUNTIFS(单笔交易!C:C,A8,单笔交易!Q:Q,"=Retrieval Request")+COUNTIF(账户调查!C:C,A8)+COUNTIF(结汇!C:C,A8) -> 17 | E8: =COUNTIFS(KYC调单!C:C,A8,KYC调单!M:M,"Personal Information")+COUNTIFS(单笔交易!C:C,A8,单笔交易!Q:Q,"Personal Information") -> 36 | F8: =SUM(B8:E8) -> 75 | G8: 2025年6月 | H8: =COUNTIFS(KYC调单!C:C,G8,KYC调单!D:D,$H$2)+COUNTIFS(单笔交易!C:C,G8,单笔交易!D:D,$H$2)+COUNTIFS(账户调查!C:C,G8,账户调查!D:D,$H$2)+COUNTIFS(警方协查!C:C,G8,警方协查!F:F,$H$2)+COUNTIFS(Recall!C:C,G8,Recall!F:F,$H$2) -> 24 | I8: =COUNTIFS(KYC调单!C:C,G8,KYC调单!D:D,$I$2)+COUNTIFS(单笔交易!C:C,G8,单笔交易!D:D,$I$2)+COUNTIFS(账户调查!C:C,G8,账户调查!D:D,$I$2)+COUNTIFS(警方协查!C:C,G8,警方协查!F:F,$I$2)+COUNTIFS(Recall!C:C,G8,Recall!F:F,$I$2) -> 25 | J8: =COUNTIFS(KYC调单!C:C,G8,KYC调单!D:D,$J$2)+COUNTIFS(单笔交易!C:C,G8,单笔交易!D:D,$J$2)+COUNTIFS(账户调查!C:C,G8,账户调查!D:D,$J$2)+COUNTIF(结汇!C:C,G8)+COUNTIFS(警方协查!C:C,G8,警方协查!F:F,$J$2)+COUNTIFS(Recall!C:C,G8,Recall!F:F,$J$2) -> 26 | K8: =SUM(H8:J8) -> 75 | L8: 2025年6月 | M8: =F8 -> 75 | N8: =(M8-M7)/M7 -> 0.13636364
A9: 2025年7月 | B9: =COUNTIFS(Recall!C:C,A9) -> 15 | C9: =COUNTIFS(警方协查!C:C,A9) -> 11 | D9: =COUNTIFS(KYC调单!C:C,A9,KYC调单!M:M,"=Retrieval Request")+COUNTIFS(单笔交易!C:C,A9,单笔交易!Q:Q,"=Retrieval Request")+COUNTIF(账户调查!C:C,A9)+COUNTIF(结汇!C:C,A9) -> 34 | E9: =COUNTIFS(KYC调单!C:C,A9,KYC调单!M:M,"Personal Information")+COUNTIFS(单笔交易!C:C,A9,单笔交易!Q:Q,"Personal Information") -> 26 | F9: =SUM(B9:E9) -> 86 | G9: 2025年7月 | H9: =COUNTIFS(KYC调单!C:C,G9,KYC调单!D:D,$H$2)+COUNTIFS(单笔交易!C:C,G9,单笔交易!D:D,$H$2)+COUNTIFS(账户调查!C:C,G9,账户调查!D:D,$H$2)+COUNTIFS(警方协查!C:C,G9,警方协查!F:F,$H$2)+COUNTIFS(Recall!C:C,G9,Recall!F:F,$H$2) -> 32 | I9: =COUNTIFS(KYC调单!C:C,G9,KYC调单!D:D,$I$2)+COUNTIFS(单笔交易!C:C,G9,单笔交易!D:D,$I$2)+COUNTIFS(账户调查!C:C,G9,账户调查!D:D,$I$2)+COUNTIFS(警方协查!C:C,G9,警方协查!F:F,$I$2)+COUNTIFS(Recall!C:C,G9,Recall!F:F,$I$2) -> 28 | J9: =COUNTIFS(KYC调单!C:C,G9,KYC调单!D:D,$J$2)+COUNTIFS(单笔交易!C:C,G9,单笔交易!D:D,$J$2)+COUNTIFS(账户调查!C:C,G9,账户调查!D:D,$J$2)+COUNTIF(结汇!C:C,G9)+COUNTIFS(警方协查!C:C,G9,警方协查!F:F,$J$2)+COUNTIFS(Recall!C:C,G9,Recall!F:F,$J$2) -> 26 | K9: =SUM(H9:J9) -> 86 | L9: 2025年7月 | M9: =F9 -> 86 | N9: =(M9-M8)/M8 -> 0.14666667
A10: 2025年8月 | B10: =COUNTIFS(Recall!C:C,A10) -> 12 | C10: =COUNTIFS(警方协查!C:C,A10) -> 5 | D10: =COUNTIFS(KYC调单!C:C,A10,KYC调单!M:M,"=Retrieval Request")+COUNTIFS(单笔交易!C:C,A10,单笔交易!Q:Q,"=Retrieval Request")+COUNTIF(账户调查!C:C,A10)+COUNTIF(结汇!C:C,A10) -> 27 | E10: =COUNTIFS(KYC调单!C:C,A10,KYC调单!M:M,"Personal Information")+COUNTIFS(单笔交易!C:C,A10,单笔交易!Q:Q,"Personal Information") -> 25 | F10: =SUM(B10:E10) -> 69 | G10: 2025年8月 | H10: =COUNTIFS(KYC调单!C:C,G10,KYC调单!D:D,$H$2)+COUNTIFS(单笔交易!C:C,G10,单笔交易!D:D,$H$2)+COUNTIFS(账户调查!C:C,G10,账户调查!D:D,$H$2)+COUNTIFS(警方协查!C:C,G10,警方协查!F:F,$H$2)+COUNTIFS(Recall!C:C,G10,Recall!F:F,$H$2) -> 22 | I10: =COUNTIFS(KYC调单!C:C,G10,KYC调单!D:D,$I$2)+COUNTIFS(单笔交易!C:C,G10,单笔交易!D:D,$I$2)+COUNTIFS(账户调查!C:C,G10,账户调查!D:D,$I$2)+COUNTIFS(警方协查!C:C,G10,警方协查!F:F,$I$2)+COUNTIFS(Recall!C:C,G10,Recall!F:F,$I$2) -> 24 | J10: =COUNTIFS(KYC调单!C:C,G10,KYC调单!D:D,$J$2)+COUNTIFS(单笔交易!C:C,G10,单笔交易!D:D,$J$2)+COUNTIFS(账户调查!C:C,G10,账户调查!D:D,$J$2)+COUNTIF(结汇!C:C,G10)+COUNTIFS(警方协查!C:C,G10,警方协查!F:F,$J$2)+COUNTIFS(Recall!C:C,G10,Recall!F:F,$J$2) -> 23 | K10: =SUM(H10:J10) -> 69 | L10: 2025年8月 | M10: =F10 -> 69 | N10: =(M10-M9)/M9 -> -0.19767442
A11: 2025年9月 | B11: =COUNTIFS(Recall!C:C,A11) -> 10 | C11: =COUNTIFS(警方协查!C:C,A11) -> 9 | D11: =COUNTIFS(KYC调单!C:C,A11,KYC调单!M:M,"=Retrieval Request")+COUNTIFS(单笔交易!C:C,A11,单笔交易!Q:Q,"=Retrieval Request")+COUNTIF(账户调查!C:C,A11)+COUNTIF(结汇!C:C,A11) -> 29 | E11: =COUNTIFS(KYC调单!C:C,A11,KYC调单!M:M,"Personal Information")+COUNTIFS(单笔交易!C:C,A11,单笔交易!Q:Q,"Personal Information") -> 28 | F11: =SUM(B11:E11) -> 76 | G11: 2025年9月 | H11: =COUNTIFS(KYC调单!C:C,G11,KYC调单!D:D,$H$2)+COUNTIFS(单笔交易!C:C,G11,单笔交易!D:D,$H$2)+COUNTIFS(账户调查!C:C,G11,账户调查!D:D,$H$2)+COUNTIFS(警方协查!C:C,G11,警方协查!F:F,$H$2)+COUNTIFS(Recall!C:C,G11,Recall!F:F,$H$2) -> 23 | I11: =COUNTIFS(KYC调单!C:C,G11,KYC调单!D:D,$I$2)+COUNTIFS(单笔交易!C:C,G11,单笔交易!D:D,$I$2)+COUNTIFS(账户调查!C:C,G11,账户调查!D:D,$I$2)+COUNTIFS(警方协查!C:C,G11,警方协查!F:F,$I$2)+COUNTIFS(Recall!C:C,G11,Recall!F:F,$I$2) -> 23 | J11: =COUNTIFS(KYC调单!C:C,G11,KYC调单!D:D,$J$2)+COUNTIFS(单笔交易!C:C,G11,单笔交易!D:D,$J$2)+COUNTIFS(账户调查!C:C,G11,账户调查!D:D,$J$2)+COUNTIF(结汇!C:C,G11)+COUNTIFS(警方协查!C:C,G11,警方协查!F:F,$J$2)+COUNTIFS(Recall!C:C,G11,Recall!F:F,$J$2) -> 30 | K11: =SUM(H11:J11) -> 76 | L11: 2025年9月 | M11: =F11 -> 76 | N11: =(M11-M10)/M10 -> 0.10144928
A12: 2025年10月 | B12: =COUNTIFS(Recall!C:C,A12) -> 7 | C12: =COUNTIFS(警方协查!C:C,A12) -> 13 | D12: =COUNTIFS(KYC调单!C:C,A12,KYC调单!M:M,"=Retrieval Request")+COUNTIFS(单笔交易!C:C,A12,单笔交易!Q:Q,"=Retrieval Request")+COUNTIF(账户调查!C:C,A12)+COUNTIF(结汇!C:C,A12) -> 32 | E12: =COUNTIFS(KYC调单!C:C,A12,KYC调单!M:M,"Personal Information")+COUNTIFS(单笔交易!C:C,A12,单笔交易!Q:Q,"Personal Information") -> 31 | F12: =SUM(B12:E12) -> 83 | G12: 2025年10月 | H12: =COUNTIFS(KYC调单!C:C,G12,KYC调单!D:D,$H$2)+COUNTIFS(单笔交易!C:C,G12,单笔交易!D:D,$H$2)+COUNTIFS(账户调查!C:C,G12,账户调查!D:D,$H$2)+COUNTIFS(警方协查!C:C,G12,警方协查!F:F,$H$2)+COUNTIFS(Recall!C:C,G12,Recall!F:F,$H$2) -> 25 | I12: =COUNTIFS(KYC调单!C:C,G12,KYC调单!D:D,$I$2)+COUNTIFS(单笔交易!C:C,G12,单笔交易!D:D,$I$2)+COUNTIFS(账户调查!C:C,G12,账户调查!D:D,$I$2)+COUNTIFS(警方协查!C:C,G12,警方协查!F:F,$I$2)+COUNTIFS(Recall!C:C,G12,Recall!F:F,$I$2) -> 24 | J12: =COUNTIFS(KYC调单!C:C,G12,KYC调单!D:D,$J$2)+COUNTIFS(单笔交易!C:C,G12,单笔交易!D:D,$J$2)+COUNTIFS(账户调查!C:C,G12,账户调查!D:D,$J$2)+COUNTIF(结汇!C:C,G12)+COUNTIFS(警方协查!C:C,G12,警方协查!F:F,$J$2)+COUNTIFS(Recall!C:C,G12,Recall!F:F,$J$2) -> 34 | K12: =SUM(H12:J12) -> 83 | L12: 2025年10月 | M12: =F12 -> 83 | N12: =(M12-M11)/M11 -> 0.092105263
A13: 2025年11月 | B13: =COUNTIFS(Recall!C:C,A13) -> 16 | C13: =COUNTIFS(警方协查!C:C,A13) -> 14 | D13: =COUNTIFS(KYC调单!C:C,A13,KYC调单!M:M,"=Retrieval Request")+COUNTIFS(单笔交易!C:C,A13,单笔交易!Q:Q,"=Retrieval Request")+COUNTIF(账户调查!C:C,A13)+COUNTIF(结汇!C:C,A13) -> 43 | E13: =COUNTIFS(KYC调单!C:C,A13,KYC调单!M:M,"Personal Information")+COUNTIFS(单笔交易!C:C,A13,单笔交易!Q:Q,"Personal Information") -> 19 | F13: =SUM(B13:E13) -> 92 | G13: 2025年11月 | H13: =COUNTIFS(KYC调单!C:C,G13,KYC调单!D:D,$H$2)+COUNTIFS(单笔交易!C:C,G13,单笔交易!D:D,$H$2)+COUNTIFS(账户调查!C:C,G13,账户调查!D:D,$H$2)+COUNTIFS(警方协查!C:C,G13,警方协查!F:F,$H$2)+COUNTIFS(Recall!C:C,G13,Recall!F:F,$H$2) -> 36 | I13: =COUNTIFS(KYC调单!C:C,G13,KYC调单!D:D,$I$2)+COUNTIFS(单笔交易!C:C,G13,单笔交易!D:D,$I$2)+COUNTIFS(账户调查!C:C,G13,账户调查!D:D,$I$2)+COUNTIFS(警方协查!C:C,G13,警方协查!F:F,$I$2)+COUNTIFS(Recall!C:C,G13,Recall!F:F,$I$2) -> 36 | J13: =COUNTIFS(KYC调单!C:C,G13,KYC调单!D:D,$J$2)+COUNTIFS(单笔交易!C:C,G13,单笔交易!D:D,$J$2)+COUNTIFS(账户调查!C:C,G13,账户调查!D:D,$J$2)+COUNTIF(结汇!C:C,G13)+COUNTIFS(警方协查!C:C,G13,警方协查!F:F,$J$2)+COUNTIFS(Recall!C:C,G13,Recall!F:F,$J$2) -> 20 | K13: =SUM(H13:J13) -> 92 | L13: 2025年11月 | M13: =F13 -> 92 | N13: =(M13-M12)/M12 -> 0.10843373
A14: 2025年12月 | B14: =COUNTIFS(Recall!C:C,A14) -> 36 | C14: =COUNTIFS(警方协查!C:C,A14) -> 9 | D14: =COUNTIFS(KYC调单!C:C,A14,KYC调单!M:M,"=Retrieval Request")+COUNTIFS(单笔交易!C:C,A14,单笔交易!Q:Q,"=Retrieval Request")+COUNTIF(账户调查!C:C,A14)+COUNTIF(结汇!C:C,A14) -> 49 | E14: =COUNTIFS(KYC调单!C:C,A14,KYC调单!M:M,"Personal Information")+COUNTIFS(单笔交易!C:C,A14,单笔交易!Q:Q,"Personal Information") -> 24 | F14: =SUM(B14:E14) -> 118 | G14: 2025年12月 | H14: =COUNTIFS(KYC调单!C:C,G14,KYC调单!D:D,$H$2)+COUNTIFS(单笔交易!C:C,G14,单笔交易!D:D,$H$2)+COUNTIFS(账户调查!C:C,G14,账户调查!D:D,$H$2)+COUNTIFS(警方协查!C:C,G14,警方协查!F:F,$H$2)+COUNTIFS(Recall!C:C,G14,Recall!F:F,$H$2) -> 35 | I14: =COUNTIFS(KYC调单!C:C,G14,KYC调单!D:D,$I$2)+COUNTIFS(单笔交易!C:C,G14,单笔交易!D:D,$I$2)+COUNTIFS(账户调查!C:C,G14,账户调查!D:D,$I$2)+COUNTIFS(警方协查!C:C,G14,警方协查!F:F,$I$2)+COUNTIFS(Recall!C:C,G14,Recall!F:F,$I$2) -> 59 | J14: =COUNTIFS(KYC调单!C:C,G14,KYC调单!D:D,$J$2)+COUNTIFS(单笔交易!C:C,G14,单笔交易!D:D,$J$2)+COUNTIFS(账户调查!C:C,G14,账户调查!D:D,$J$2)+COUNTIF(结汇!C:C,G14)+COUNTIFS(警方协查!C:C,G14,警方协查!F:F,$J$2)+COUNTIFS(Recall!C:C,G14,Recall!F:F,$J$2) -> 24 | K14: =SUM(H14:J14) -> 118 | L14: 2025年12月 | M14: =F14 -> 118 | N14: =(M14-M13)/M13 -> 0.2826087
... A20: 2026年6月 | B20: =COUNTIFS(Recall!C:C,A20) -> 27 | C20: =COUNTIFS(警方协查!C:C,A20) -> 19 | D20: =COUNTIFS(KYC调单!C:C,A20,KYC调单!M:M,"=Retrieval Request")+COUNTIFS(单笔交易!C:C,A20,单笔交易!Q:Q,"=Retrieval Request")+COUNTIF(账户调查!C:C,A20)+COUNTIF(结汇!C:C,A20) -> 48 | E20: =COUNTIFS(KYC调单!C:C,A20,KYC调单!M:M,"Personal Information")+COUNTIFS(单笔交易!C:C,A20,单笔交易!Q:Q,"Personal Information") -> 12 | F20: =SUM(B20:E20) -> 106 | G20: 2026年6月 | H20: =COUNTIFS(KYC调单!C:C,G20,KYC调单!D:D,$H$2)+COUNTIFS(单笔交易!C:C,G20,单笔交易!D:D,$H$2)+COUNTIFS(账户调查!C:C,G20,账户调查!D:D,$H$2)+COUNTIFS(警方协查!C:C,G20,警方协查!F:F,$H$2)+COUNTIFS(Recall!C:C,G20,Recall!F:F,$H$2) -> 54 | I20: =COUNTIFS(KYC调单!C:C,G20,KYC调单!D:D,$I$2)+COUNTIFS(单笔交易!C:C,G20,单笔交易!D:D,$I$2)+COUNTIFS(账户调查!C:C,G20,账户调查!D:D,$I$2)+COUNTIFS(警方协查!C:C,G20,警方协查!F:F,$I$2)+COUNTIFS(Recall!C:C,G20,Recall!F:F,$I$2) -> 34 | J20: =COUNTIFS(KYC调单!C:C,G20,KYC调单!D:D,$J$2)+COUNTIFS(单笔交易!C:C,G20,单笔交易!D:D,$J$2)+COUNTIFS(账户调查!C:C,G20,账户调查!D:D,$J$2)+COUNTIF(结汇!C:C,G20)+COUNTIFS(警方协查!C:C,G20,警方协查!F:F,$J$2)+COUNTIFS(Recall!C:C,G20,Recall!F:F,$J$2) -> 18 | K20: =SUM(H20:J20) -> 106 | L20: 2026年6月 | M20: =F20 -> 106 | N20: =(M20-M19)/M19 -> -0.24822695
A21: 2026年7月
A22: 2026年8月
A23: 2026年9月
A24: 2026年10月
A25: 2026年11月
A26: 2026年12月
A34: 每月调单数量（以渠道分类）
A35: 时间 | B35: DBS | C35: Banking Circle | D35: M-DAQ | E35: GME | F35: QBC | G35: Thunes | H35: 结汇渠道 | I35: 平安银行 | J35: PING PONG | K35: SCB | L35: Baokim | M35: 其他 | N35: Nium | O35: Openpayd | P35: IBC | Q35: TransferMate | S35: 每月总和 | T35: 是否与调单类型分类一致
A36: 2025年1月 | B36: =COUNTIFS(KYC调单!C:C,A3,KYC调单!E:E,"DBS")+COUNTIFS(单笔交易!C:C,A3,单笔交易!H:H,"DBS")+COUNTIFS(账户调查!C:C,A3,账户调查!F:F,"DBS")+COUNTIFS(Recall!C:C,A3,Recall!D:D,"DBS")+COUNTIFS(警方协查!C:C,A3,警方协查!E:E,"DBS") -> 14 | C36: =COUNTIFS(KYC调单!C:C,A3,KYC调单!E:E,"Banking Circle")+COUNTIFS(单笔交易!C:C,A3,单笔交易!H:H,"Banking Circle")+COUNTIFS(账户调查!C:C,A3,账户调查!F:F,"Banking Circle")+COUNTIFS(Recall!C:C,A3,Recall!D:D,"Banking Circle")+COUNTIFS(警方协查!C:C,A3,警方协查!E:E,"Banking Circle") -> 36 | D36: =COUNTIFS(KYC调单!C:C,A3,KYC调单!E:E,"M-DAQ")+COUNTIFS(单笔交易!C:C,A3,单笔交易!H:H,"M-DAQ")+COUNTIFS(账户调查!C:C,A3,账户调查!F:F,"M-DAQ")+COUNTIFS(Recall!C:C,A3,Recall!D:D,"M-DAQ")+COUNTIFS(警方协查!C:C,A3,警方协查!E:E,"M-DAQ") -> 0 | E36: =COUNTIFS(KYC调单!C:C,A3,KYC调单!E:E,"GME")+COUNTIFS(单笔交易!C:C,A3,单笔交易!H:H,"GME")+COUNTIFS(账户调查!C:C,A3,账户调查!F:F,"GME")+COUNTIFS(Recall!C:C,A3,Recall!D:D,"GME")+COUNTIFS(警方协查!C:C,A3,警方协查!E:E,"GME") -> 2 | F36: =COUNTIFS(KYC调单!C:C,A3,KYC调单!E:E,"QBC")+COUNTIFS(单笔交易!C:C,A3,单笔交易!H:H,"QBC")+COUNTIFS(账户调查!C:C,A3,账户调查!F:F,"QBC")+COUNTIFS(Recall!C:C,A3,Recall!D:D,"QBC")+COUNTIFS(警方协查!C:C,A3,警方协查!E:E,"QBC") -> 0 | G36: =COUNTIFS(KYC调单!C:C,A3,KYC调单!E:E,"Thunes")+COUNTIFS(单笔交易!C:C,A3,单笔交易!H:H,"Thunes")+COUNTIFS(账户调查!C:C,A3,账户调查!F:F,"Thunes")+COUNTIFS(Recall!C:C,A3,Recall!D:D,"Thunes")+COUNTIFS(警方协查!C:C,A3,警方协查!E:E,"Thunes") -> 1 | H36: =COUNTIF(结汇!C:C,A3) -> 2 | I36: =COUNTIFS(KYC调单!C:C,A3,KYC调单!E:E,"平安银行")+COUNTIFS(单笔交易!C:C,A3,单笔交易!H:H,"平安银行")+COUNTIFS(账户调查!C:C,A3,账户调查!F:F,"平安银行")+COUNTIFS(Recall!C:C,A3,Recall!D:D,"平安银行")+COUNTIFS(警方协查!C:C,A3,警方协查!E:E,"平安银行") -> 0 | J36: =COUNTIFS(KYC调单!C:C,A3,KYC调单!E:E,"PING PONG")+COUNTIFS(单笔交易!C:C,A3,单笔交易!H:H,"PING PONG")+COUNTIFS(账户调查!C:C,A3,账户调查!F:F,"PING PONG")+COUNTIFS(Recall!C:C,A3,Recall!D:D,"PING PONG")+COUNTIFS(警方协查!C:C,A3,警方协查!E:E,"PING PONG") -> 1 | K36: =COUNTIFS(单笔交易!C:C,A36,单笔交易!H:H,"SCB")+COUNTIFS(账户调查!C:C,A36,账户调查!F:F,"SCB")+COUNTIFS(Recall!C:C,A36,Recall!D:D,"SCB") -> 0 | L36: =COUNTIFS(单笔交易!C:C,A36,单笔交易!H:H,"Baokim")+COUNTIFS(账户调查!C:C,A36,账户调查!F:F,"Baokim") -> 0 | M36: =COUNTIFS(警方协查!C:C,A36,警方协查!E:E,"其他警方")+COUNTIFS(账户调查!C:C,A36,账户调查!F:F,"Payoneer")+COUNTIFS(账户调查!C:C,A36,账户调查!F:F,"DSGpay")+COUNTIFS(单笔交易!C:C,A36,单笔交易!H:H,"DSGpay")+COUNTIFS(单笔交易!C:C,A36,单笔交易!H:H,"Moolahgo")+COUNTIFS(账户调查!C:C,A36,账户调查!F:F,"Sentbe")+COUNTIFS(账户调查!C:C,A36,账户调查!F:F,"flutterwave")+COUNTIFS(单笔交易!C:C,A36,单笔交易!H:H,"Pyvio")+COUNTIFS(账户调查!C:C,A36,账户调查!F:F,"HPAY") -> 1 | N36: =COUNTIFS(单笔交易!C:C,A36,单笔交易!H:H,"Nium")+COUNTIFS(账户调查!C:C,A36,账户调查!F:F,"Nium")+COUNTIFS(KYC调单!C:C,A3,KYC调单!E:E,"Nium") -> 0 | O36: =COUNTIFS(警方协查!C:C,A36,警方协查!E:E,"OpenPayd")+COUNTIFS(单笔交易!C:C,A36,单笔交易!H:H,"OpenPayd")+COUNTIFS(账户调查!C:C,A36,账户调查!F:F,"OpenPayd")+COUNTIFS(Recall!C:C,A36,Recall!D:D,"OpenPayd") -> 0 | P36: =COUNTIFS(KYC调单!C:C,A3,KYC调单!E:E,"IBC")+COUNTIFS(单笔交易!C:C,A3,单笔交易!H:H,"IBC")+COUNTIFS(账户调查!C:C,A3,账户调查!F:F,"IBC") -> 0 | Q36: =COUNTIFS(KYC调单!C:C,A36,KYC调单!E:E,"TransferMate")+COUNTIFS(单笔交易!C:C,A36,单笔交易!H:H,"TransferMate")+COUNTIFS(账户调查!C:C,A36,账户调查!F:F,"TransferMate") -> 0 | S36: =SUM(B36:R36) -> 57 | T36: =_xlfn.IFS(S36=F3,"一致") -> 一致
A37: 2025年2月 | B37: =COUNTIFS(KYC调单!C:C,A4,KYC调单!E:E,"DBS")+COUNTIFS(单笔交易!C:C,A4,单笔交易!H:H,"DBS")+COUNTIFS(账户调查!C:C,A4,账户调查!F:F,"DBS")+COUNTIFS(Recall!C:C,A4,Recall!D:D,"DBS")+COUNTIFS(警方协查!C:C,A4,警方协查!E:E,"DBS") -> 22 | C37: =COUNTIFS(KYC调单!C:C,A4,KYC调单!E:E,"Banking Circle")+COUNTIFS(单笔交易!C:C,A4,单笔交易!H:H,"Banking Circle")+COUNTIFS(账户调查!C:C,A4,账户调查!F:F,"Banking Circle")+COUNTIFS(Recall!C:C,A4,Recall!D:D,"Banking Circle")+COUNTIFS(警方协查!C:C,A4,警方协查!E:E,"Banking Circle") -> 19 | D37: =COUNTIFS(KYC调单!C:C,A4,KYC调单!E:E,"M-DAQ")+COUNTIFS(单笔交易!C:C,A4,单笔交易!H:H,"M-DAQ")+COUNTIFS(账户调查!C:C,A4,账户调查!F:F,"M-DAQ")+COUNTIFS(Recall!C:C,A4,Recall!D:D,"M-DAQ")+COUNTIFS(警方协查!C:C,A4,警方协查!E:E,"M-DAQ") -> 0 | E37: =COUNTIFS(KYC调单!C:C,A4,KYC调单!E:E,"GME")+COUNTIFS(单笔交易!C:C,A4,单笔交易!H:H,"GME")+COUNTIFS(账户调查!C:C,A4,账户调查!F:F,"GME")+COUNTIFS(Recall!C:C,A4,Recall!D:D,"GME")+COUNTIFS(警方协查!C:C,A4,警方协查!E:E,"GME") -> 0 | F37: =COUNTIFS(KYC调单!C:C,A4,KYC调单!E:E,"QBC")+COUNTIFS(单笔交易!C:C,A4,单笔交易!H:H,"QBC")+COUNTIFS(账户调查!C:C,A4,账户调查!F:F,"QBC")+COUNTIFS(Recall!C:C,A4,Recall!D:D,"QBC")+COUNTIFS(警方协查!C:C,A4,警方协查!E:E,"QBC") -> 0 | G37: =COUNTIFS(KYC调单!C:C,A4,KYC调单!E:E,"Thunes")+COUNTIFS(单笔交易!C:C,A4,单笔交易!H:H,"Thunes")+COUNTIFS(账户调查!C:C,A4,账户调查!F:F,"Thunes")+COUNTIFS(Recall!C:C,A4,Recall!D:D,"Thunes")+COUNTIFS(警方协查!C:C,A4,警方协查!E:E,"Thunes") -> 0 | H37: =COUNTIF(结汇!C:C,A4) -> 1 | I37: =COUNTIFS(KYC调单!C:C,A4,KYC调单!E:E,"平安银行")+COUNTIFS(单笔交易!C:C,A4,单笔交易!H:H,"平安银行")+COUNTIFS(账户调查!C:C,A4,账户调查!F:F,"平安银行")+COUNTIFS(Recall!C:C,A4,Recall!D:D,"平安银行")+COUNTIFS(警方协查!C:C,A4,警方协查!E:E,"平安银行") -> 0 | J37: =COUNTIFS(KYC调单!C:C,A4,KYC调单!E:E,"PING PONG")+COUNTIFS(单笔交易!C:C,A4,单笔交易!H:H,"PING PONG")+COUNTIFS(账户调查!C:C,A4,账户调查!F:F,"PING PONG")+COUNTIFS(Recall!C:C,A4,Recall!D:D,"PING PONG")+COUNTIFS(警方协查!C:C,A4,警方协查!E:E,"PING PONG") -> 0 | K37: =COUNTIFS(单笔交易!C:C,A37,单笔交易!H:H,"SCB")+COUNTIFS(账户调查!C:C,A37,账户调查!F:F,"SCB")+COUNTIFS(Recall!C:C,A37,Recall!D:D,"SCB") -> 0 | L37: =COUNTIFS(单笔交易!C:C,A37,单笔交易!H:H,"Baokim")+COUNTIFS(账户调查!C:C,A37,账户调查!F:F,"Baokim") -> 0 | M37: =COUNTIFS(警方协查!C:C,A37,警方协查!E:E,"其他警方")+COUNTIFS(账户调查!C:C,A37,账户调查!F:F,"Payoneer")+COUNTIFS(账户调查!C:C,A37,账户调查!F:F,"DSGpay")+COUNTIFS(单笔交易!C:C,A37,单笔交易!H:H,"DSGpay")+COUNTIFS(单笔交易!C:C,A37,单笔交易!H:H,"Moolahgo")+COUNTIFS(账户调查!C:C,A37,账户调查!F:F,"Sentbe")+COUNTIFS(账户调查!C:C,A37,账户调查!F:F,"flutterwave")+COUNTIFS(单笔交易!C:C,A37,单笔交易!H:H,"Pyvio")+COUNTIFS(账户调查!C:C,A37,账户调查!F:F,"HPAY") -> 0 | N37: =COUNTIFS(单笔交易!C:C,A37,单笔交易!H:H,"Nium")+COUNTIFS(账户调查!C:C,A37,账户调查!F:F,"Nium")+COUNTIFS(KYC调单!C:C,A4,KYC调单!E:E,"Nium") -> 0 | O37: =COUNTIFS(警方协查!C:C,A37,警方协查!E:E,"OpenPayd")+COUNTIFS(单笔交易!C:C,A37,单笔交易!H:H,"OpenPayd")+COUNTIFS(账户调查!C:C,A37,账户调查!F:F,"OpenPayd")+COUNTIFS(Recall!C:C,A37,Recall!D:D,"OpenPayd") -> 0 | P37: =COUNTIFS(KYC调单!C:C,A4,KYC调单!E:E,"IBC")+COUNTIFS(单笔交易!C:C,A4,单笔交易!H:H,"IBC")+COUNTIFS(账户调查!C:C,A4,账户调查!F:F,"IBC") -> 0 | Q37: =COUNTIFS(KYC调单!C:C,A37,KYC调单!E:E,"TransferMate")+COUNTIFS(单笔交易!C:C,A37,单笔交易!H:H,"TransferMate")+COUNTIFS(账户调查!C:C,A37,账户调查!F:F,"TransferMate") -> 0 | S37: =SUM(B37:R37) -> 42 | T37: =_xlfn.IFS(S37=F4,"一致") -> 一致
A38: 2025年3月 | B38: =COUNTIFS(KYC调单!C:C,A5,KYC调单!E:E,"DBS")+COUNTIFS(单笔交易!C:C,A5,单笔交易!H:H,"DBS")+COUNTIFS(账户调查!C:C,A5,账户调查!F:F,"DBS")+COUNTIFS(Recall!C:C,A5,Recall!D:D,"DBS")+COUNTIFS(警方协查!C:C,A5,警方协查!E:E,"DBS") -> 24 | C38: =COUNTIFS(KYC调单!C:C,A5,KYC调单!E:E,"Banking Circle")+COUNTIFS(单笔交易!C:C,A5,单笔交易!H:H,"Banking Circle")+COUNTIFS(账户调查!C:C,A5,账户调查!F:F,"Banking Circle")+COUNTIFS(Recall!C:C,A5,Recall!D:D,"Banking Circle")+COUNTIFS(警方协查!C:C,A5,警方协查!E:E,"Banking Circle") -> 21 | D38: =COUNTIFS(KYC调单!C:C,A5,KYC调单!E:E,"M-DAQ")+COUNTIFS(单笔交易!C:C,A5,单笔交易!H:H,"M-DAQ")+COUNTIFS(账户调查!C:C,A5,账户调查!F:F,"M-DAQ")+COUNTIFS(Recall!C:C,A5,Recall!D:D,"M-DAQ")+COUNTIFS(警方协查!C:C,A5,警方协查!E:E,"M-DAQ") -> 8 | E38: =COUNTIFS(KYC调单!C:C,A5,KYC调单!E:E,"GME")+COUNTIFS(单笔交易!C:C,A5,单笔交易!H:H,"GME")+COUNTIFS(账户调查!C:C,A5,账户调查!F:F,"GME")+COUNTIFS(Recall!C:C,A5,Recall!D:D,"GME")+COUNTIFS(警方协查!C:C,A5,警方协查!E:E,"GME") -> 1 | F38: =COUNTIFS(KYC调单!C:C,A5,KYC调单!E:E,"QBC")+COUNTIFS(单笔交易!C:C,A5,单笔交易!H:H,"QBC")+COUNTIFS(账户调查!C:C,A5,账户调查!F:F,"QBC")+COUNTIFS(Recall!C:C,A5,Recall!D:D,"QBC")+COUNTIFS(警方协查!C:C,A5,警方协查!E:E,"QBC") -> 0 | G38: =COUNTIFS(KYC调单!C:C,A5,KYC调单!E:E,"Thunes")+COUNTIFS(单笔交易!C:C,A5,单笔交易!H:H,"Thunes")+COUNTIFS(账户调查!C:C,A5,账户调查!F:F,"Thunes")+COUNTIFS(Recall!C:C,A5,Recall!D:D,"Thunes")+COUNTIFS(警方协查!C:C,A5,警方协查!E:E,"Thunes") -> 2 | H38: =COUNTIF(结汇!C:C,A5) -> 1 | I38: =COUNTIFS(KYC调单!C:C,A5,KYC调单!E:E,"平安银行")+COUNTIFS(单笔交易!C:C,A5,单笔交易!H:H,"平安银行")+COUNTIFS(账户调查!C:C,A5,账户调查!F:F,"平安银行")+COUNTIFS(Recall!C:C,A5,Recall!D:D,"平安银行")+COUNTIFS(警方协查!C:C,A5,警方协查!E:E,"平安银行") -> 3 | J38: =COUNTIFS(KYC调单!C:C,A5,KYC调单!E:E,"PING PONG")+COUNTIFS(单笔交易!C:C,A5,单笔交易!H:H,"PING PONG")+COUNTIFS(账户调查!C:C,A5,账户调查!F:F,"PING PONG")+COUNTIFS(Recall!C:C,A5,Recall!D:D,"PING PONG")+COUNTIFS(警方协查!C:C,A5,警方协查!E:E,"PING PONG") -> 0 | K38: =COUNTIFS(单笔交易!C:C,A38,单笔交易!H:H,"SCB")+COUNTIFS(账户调查!C:C,A38,账户调查!F:F,"SCB")+COUNTIFS(Recall!C:C,A38,Recall!D:D,"SCB") -> 0 | L38: =COUNTIFS(单笔交易!C:C,A38,单笔交易!H:H,"Baokim")+COUNTIFS(账户调查!C:C,A38,账户调查!F:F,"Baokim") -> 0 | M38: =COUNTIFS(警方协查!C:C,A38,警方协查!E:E,"其他警方")+COUNTIFS(账户调查!C:C,A38,账户调查!F:F,"Payoneer")+COUNTIFS(账户调查!C:C,A38,账户调查!F:F,"DSGpay")+COUNTIFS(单笔交易!C:C,A38,单笔交易!H:H,"DSGpay")+COUNTIFS(单笔交易!C:C,A38,单笔交易!H:H,"Moolahgo")+COUNTIFS(账户调查!C:C,A38,账户调查!F:F,"Sentbe")+COUNTIFS(账户调查!C:C,A38,账户调查!F:F,"flutterwave")+COUNTIFS(单笔交易!C:C,A38,单笔交易!H:H,"Pyvio")+COUNTIFS(账户调查!C:C,A38,账户调查!F:F,"HPAY") -> 0 | N38: =COUNTIFS(单笔交易!C:C,A38,单笔交易!H:H,"Nium")+COUNTIFS(账户调查!C:C,A38,账户调查!F:F,"Nium")+COUNTIFS(KYC调单!C:C,A5,KYC调单!E:E,"Nium") -> 0 | O38: =COUNTIFS(警方协查!C:C,A38,警方协查!E:E,"OpenPayd")+COUNTIFS(单笔交易!C:C,A38,单笔交易!H:H,"OpenPayd")+COUNTIFS(账户调查!C:C,A38,账户调查!F:F,"OpenPayd")+COUNTIFS(Recall!C:C,A38,Recall!D:D,"OpenPayd") -> 0 | P38: =COUNTIFS(KYC调单!C:C,A5,KYC调单!E:E,"IBC")+COUNTIFS(单笔交易!C:C,A5,单笔交易!H:H,"IBC")+COUNTIFS(账户调查!C:C,A5,账户调查!F:F,"IBC") -> 0 | Q38: =COUNTIFS(KYC调单!C:C,A38,KYC调单!E:E,"TransferMate")+COUNTIFS(单笔交易!C:C,A38,单笔交易!H:H,"TransferMate")+COUNTIFS(账户调查!C:C,A38,账户调查!F:F,"TransferMate") -> 0 | S38: =SUM(B38:R38) -> 60 | T38: =_xlfn.IFS(S38=F5,"一致") -> 一致
A39: 2025年4月 | B39: =COUNTIFS(KYC调单!C:C,A6,KYC调单!E:E,"DBS")+COUNTIFS(单笔交易!C:C,A6,单笔交易!H:H,"DBS")+COUNTIFS(账户调查!C:C,A6,账户调查!F:F,"DBS")+COUNTIFS(Recall!C:C,A6,Recall!D:D,"DBS")+COUNTIFS(警方协查!C:C,A6,警方协查!E:E,"DBS") -> 32 | C39: =COUNTIFS(KYC调单!C:C,A6,KYC调单!E:E,"Banking Circle")+COUNTIFS(单笔交易!C:C,A6,单笔交易!H:H,"Banking Circle")+COUNTIFS(账户调查!C:C,A6,账户调查!F:F,"Banking Circle")+COUNTIFS(Recall!C:C,A6,Recall!D:D,"Banking Circle")+COUNTIFS(警方协查!C:C,A6,警方协查!E:E,"Banking Circle") -> 14 | D39: =COUNTIFS(KYC调单!C:C,A6,KYC调单!E:E,"M-DAQ")+COUNTIFS(单笔交易!C:C,A6,单笔交易!H:H,"M-DAQ")+COUNTIFS(账户调查!C:C,A6,账户调查!F:F,"M-DAQ")+COUNTIFS(Recall!C:C,A6,Recall!D:D,"M-DAQ")+COUNTIFS(警方协查!C:C,A6,警方协查!E:E,"M-DAQ") -> 5 | E39: =COUNTIFS(KYC调单!C:C,A6,KYC调单!E:E,"GME")+COUNTIFS(单笔交易!C:C,A6,单笔交易!H:H,"GME")+COUNTIFS(账户调查!C:C,A6,账户调查!F:F,"GME")+COUNTIFS(Recall!C:C,A6,Recall!D:D,"GME")+COUNTIFS(警方协查!C:C,A6,警方协查!E:E,"GME") -> 2 | F39: =COUNTIFS(KYC调单!C:C,A6,KYC调单!E:E,"QBC")+COUNTIFS(单笔交易!C:C,A6,单笔交易!H:H,"QBC")+COUNTIFS(账户调查!C:C,A6,账户调查!F:F,"QBC")+COUNTIFS(Recall!C:C,A6,Recall!D:D,"QBC")+COUNTIFS(警方协查!C:C,A6,警方协查!E:E,"QBC") -> 0 | G39: =COUNTIFS(KYC调单!C:C,A6,KYC调单!E:E,"Thunes")+COUNTIFS(单笔交易!C:C,A6,单笔交易!H:H,"Thunes")+COUNTIFS(账户调查!C:C,A6,账户调查!F:F,"Thunes")+COUNTIFS(Recall!C:C,A6,Recall!D:D,"Thunes")+COUNTIFS(警方协查!C:C,A6,警方协查!E:E,"Thunes") -> 0 | H39: =COUNTIF(结汇!C:C,A6) -> 3 | I39: =COUNTIFS(KYC调单!C:C,A6,KYC调单!E:E,"平安银行")+COUNTIFS(单笔交易!C:C,A6,单笔交易!H:H,"平安银行")+COUNTIFS(账户调查!C:C,A6,账户调查!F:F,"平安银行")+COUNTIFS(Recall!C:C,A6,Recall!D:D,"平安银行")+COUNTIFS(警方协查!C:C,A6,警方协查!E:E,"平安银行") -> 0 | J39: =COUNTIFS(KYC调单!C:C,A6,KYC调单!E:E,"PING PONG")+COUNTIFS(单笔交易!C:C,A6,单笔交易!H:H,"PING PONG")+COUNTIFS(账户调查!C:C,A6,账户调查!F:F,"PING PONG")+COUNTIFS(Recall!C:C,A6,Recall!D:D,"PING PONG")+COUNTIFS(警方协查!C:C,A6,警方协查!E:E,"PING PONG") -> 0 | K39: =COUNTIFS(单笔交易!C:C,A39,单笔交易!H:H,"SCB")+COUNTIFS(账户调查!C:C,A39,账户调查!F:F,"SCB")+COUNTIFS(Recall!C:C,A39,Recall!D:D,"SCB") -> 0 | L39: =COUNTIFS(单笔交易!C:C,A39,单笔交易!H:H,"Baokim")+COUNTIFS(账户调查!C:C,A39,账户调查!F:F,"Baokim") -> 0 | M39: =COUNTIFS(警方协查!C:C,A39,警方协查!E:E,"其他警方")+COUNTIFS(账户调查!C:C,A39,账户调查!F:F,"Payoneer")+COUNTIFS(账户调查!C:C,A39,账户调查!F:F,"DSGpay")+COUNTIFS(单笔交易!C:C,A39,单笔交易!H:H,"DSGpay")+COUNTIFS(单笔交易!C:C,A39,单笔交易!H:H,"Moolahgo")+COUNTIFS(账户调查!C:C,A39,账户调查!F:F,"Sentbe")+COUNTIFS(账户调查!C:C,A39,账户调查!F:F,"flutterwave")+COUNTIFS(单笔交易!C:C,A39,单笔交易!H:H,"Pyvio")+COUNTIFS(账户调查!C:C,A39,账户调查!F:F,"HPAY") -> 0 | N39: =COUNTIFS(单笔交易!C:C,A39,单笔交易!H:H,"Nium")+COUNTIFS(账户调查!C:C,A39,账户调查!F:F,"Nium")+COUNTIFS(KYC调单!C:C,A6,KYC调单!E:E,"Nium") -> 0 | O39: =COUNTIFS(警方协查!C:C,A39,警方协查!E:E,"OpenPayd")+COUNTIFS(单笔交易!C:C,A39,单笔交易!H:H,"OpenPayd")+COUNTIFS(账户调查!C:C,A39,账户调查!F:F,"OpenPayd")+COUNTIFS(Recall!C:C,A39,Recall!D:D,"OpenPayd") -> 0 | P39: =COUNTIFS(KYC调单!C:C,A6,KYC调单!E:E,"IBC")+COUNTIFS(单笔交易!C:C,A6,单笔交易!H:H,"IBC")+COUNTIFS(账户调查!C:C,A6,账户调查!F:F,"IBC") -> 0 | Q39: =COUNTIFS(KYC调单!C:C,A39,KYC调单!E:E,"TransferMate")+COUNTIFS(单笔交易!C:C,A39,单笔交易!H:H,"TransferMate")+COUNTIFS(账户调查!C:C,A39,账户调查!F:F,"TransferMate") -> 0 | S39: =SUM(B39:R39) -> 56 | T39: =_xlfn.IFS(S39=F6,"一致") -> 一致
A40: 2025年5月 | B40: =COUNTIFS(KYC调单!C:C,A7,KYC调单!E:E,"DBS")+COUNTIFS(单笔交易!C:C,A7,单笔交易!H:H,"DBS")+COUNTIFS(账户调查!C:C,A7,账户调查!F:F,"DBS")+COUNTIFS(Recall!C:C,A7,Recall!D:D,"DBS")+COUNTIFS(警方协查!C:C,A7,警方协查!E:E,"DBS") -> 40 | C40: =COUNTIFS(KYC调单!C:C,A7,KYC调单!E:E,"Banking Circle")+COUNTIFS(单笔交易!C:C,A7,单笔交易!H:H,"Banking Circle")+COUNTIFS(账户调查!C:C,A7,账户调查!F:F,"Banking Circle")+COUNTIFS(Recall!C:C,A7,Recall!D:D,"Banking Circle")+COUNTIFS(警方协查!C:C,A7,警方协查!E:E,"Banking Circle") -> 21 | D40: =COUNTIFS(KYC调单!C:C,A7,KYC调单!E:E,"M-DAQ")+COUNTIFS(单笔交易!C:C,A7,单笔交易!H:H,"M-DAQ")+COUNTIFS(账户调查!C:C,A7,账户调查!F:F,"M-DAQ")+COUNTIFS(Recall!C:C,A7,Recall!D:D,"M-DAQ")+COUNTIFS(警方协查!C:C,A7,警方协查!E:E,"M-DAQ") -> 1 | E40: =COUNTIFS(KYC调单!C:C,A7,KYC调单!E:E,"GME")+COUNTIFS(单笔交易!C:C,A7,单笔交易!H:H,"GME")+COUNTIFS(账户调查!C:C,A7,账户调查!F:F,"GME")+COUNTIFS(Recall!C:C,A7,Recall!D:D,"GME")+COUNTIFS(警方协查!C:C,A7,警方协查!E:E,"GME") -> 1 | F40: =COUNTIFS(KYC调单!C:C,A7,KYC调单!E:E,"QBC")+COUNTIFS(单笔交易!C:C,A7,单笔交易!H:H,"QBC")+COUNTIFS(账户调查!C:C,A7,账户调查!F:F,"QBC")+COUNTIFS(Recall!C:C,A7,Recall!D:D,"QBC")+COUNTIFS(警方协查!C:C,A7,警方协查!E:E,"QBC") -> 1 | G40: =COUNTIFS(KYC调单!C:C,A7,KYC调单!E:E,"Thunes")+COUNTIFS(单笔交易!C:C,A7,单笔交易!H:H,"Thunes")+COUNTIFS(账户调查!C:C,A7,账户调查!F:F,"Thunes")+COUNTIFS(Recall!C:C,A7,Recall!D:D,"Thunes")+COUNTIFS(警方协查!C:C,A7,警方协查!E:E,"Thunes") -> 1 | H40: =COUNTIF(结汇!C:C,A7) -> 1 | I40: =COUNTIFS(KYC调单!C:C,A7,KYC调单!E:E,"平安银行")+COUNTIFS(单笔交易!C:C,A7,单笔交易!H:H,"平安银行")+COUNTIFS(账户调查!C:C,A7,账户调查!F:F,"平安银行")+COUNTIFS(Recall!C:C,A7,Recall!D:D,"平安银行")+COUNTIFS(警方协查!C:C,A7,警方协查!E:E,"平安银行") -> 0 | J40: =COUNTIFS(KYC调单!C:C,A7,KYC调单!E:E,"PING PONG")+COUNTIFS(单笔交易!C:C,A7,单笔交易!H:H,"PING PONG")+COUNTIFS(账户调查!C:C,A7,账户调查!F:F,"PING PONG")+COUNTIFS(Recall!C:C,A7,Recall!D:D,"PING PONG")+COUNTIFS(警方协查!C:C,A7,警方协查!E:E,"PING PONG") -> 0 | K40: =COUNTIFS(单笔交易!C:C,A40,单笔交易!H:H,"SCB")+COUNTIFS(账户调查!C:C,A40,账户调查!F:F,"SCB")+COUNTIFS(Recall!C:C,A40,Recall!D:D,"SCB") -> 0 | L40: =COUNTIFS(单笔交易!C:C,A40,单笔交易!H:H,"Baokim")+COUNTIFS(账户调查!C:C,A40,账户调查!F:F,"Baokim") -> 0 | M40: =COUNTIFS(警方协查!C:C,A40,警方协查!E:E,"其他警方")+COUNTIFS(账户调查!C:C,A40,账户调查!F:F,"Payoneer")+COUNTIFS(账户调查!C:C,A40,账户调查!F:F,"DSGpay")+COUNTIFS(单笔交易!C:C,A40,单笔交易!H:H,"DSGpay")+COUNTIFS(单笔交易!C:C,A40,单笔交易!H:H,"Moolahgo")+COUNTIFS(账户调查!C:C,A40,账户调查!F:F,"Sentbe")+COUNTIFS(账户调查!C:C,A40,账户调查!F:F,"flutterwave")+COUNTIFS(单笔交易!C:C,A40,单笔交易!H:H,"Pyvio")+COUNTIFS(账户调查!C:C,A40,账户调查!F:F,"HPAY") -> 0 | N40: =COUNTIFS(单笔交易!C:C,A40,单笔交易!H:H,"Nium")+COUNTIFS(账户调查!C:C,A40,账户调查!F:F,"Nium")+COUNTIFS(KYC调单!C:C,A7,KYC调单!E:E,"Nium") -> 0 | O40: =COUNTIFS(警方协查!C:C,A40,警方协查!E:E,"OpenPayd")+COUNTIFS(单笔交易!C:C,A40,单笔交易!H:H,"OpenPayd")+COUNTIFS(账户调查!C:C,A40,账户调查!F:F,"OpenPayd")+COUNTIFS(Recall!C:C,A40,Recall!D:D,"OpenPayd") -> 0 | P40: =COUNTIFS(KYC调单!C:C,A7,KYC调单!E:E,"IBC")+COUNTIFS(单笔交易!C:C,A7,单笔交易!H:H,"IBC")+COUNTIFS(账户调查!C:C,A7,账户调查!F:F,"IBC") -> 0 | Q40: =COUNTIFS(KYC调单!C:C,A40,KYC调单!E:E,"TransferMate")+COUNTIFS(单笔交易!C:C,A40,单笔交易!H:H,"TransferMate")+COUNTIFS(账户调查!C:C,A40,账户调查!F:F,"TransferMate") -> 0 | S40: =SUM(B40:R40) -> 66 | T40: =_xlfn.IFS(S40=F7,"一致") -> 一致
A41: 2025年6月 | B41: =COUNTIFS(KYC调单!C:C,A8,KYC调单!E:E,"DBS")+COUNTIFS(单笔交易!C:C,A8,单笔交易!H:H,"DBS")+COUNTIFS(账户调查!C:C,A8,账户调查!F:F,"DBS")+COUNTIFS(Recall!C:C,A8,Recall!D:D,"DBS")+COUNTIFS(警方协查!C:C,A8,警方协查!E:E,"DBS") -> 38 | C41: =COUNTIFS(KYC调单!C:C,A8,KYC调单!E:E,"Banking Circle")+COUNTIFS(单笔交易!C:C,A8,单笔交易!H:H,"Banking Circle")+COUNTIFS(账户调查!C:C,A8,账户调查!F:F,"Banking Circle")+COUNTIFS(Recall!C:C,A8,Recall!D:D,"Banking Circle")+COUNTIFS(警方协查!C:C,A8,警方协查!E:E,"Banking Circle") -> 28 | D41: =COUNTIFS(KYC调单!C:C,A8,KYC调单!E:E,"M-DAQ")+COUNTIFS(单笔交易!C:C,A8,单笔交易!H:H,"M-DAQ")+COUNTIFS(账户调查!C:C,A8,账户调查!F:F,"M-DAQ")+COUNTIFS(Recall!C:C,A8,Recall!D:D,"M-DAQ")+COUNTIFS(警方协查!C:C,A8,警方协查!E:E,"M-DAQ") -> 0 | E41: =COUNTIFS(KYC调单!C:C,A8,KYC调单!E:E,"GME")+COUNTIFS(单笔交易!C:C,A8,单笔交易!H:H,"GME")+COUNTIFS(账户调查!C:C,A8,账户调查!F:F,"GME")+COUNTIFS(Recall!C:C,A8,Recall!D:D,"GME")+COUNTIFS(警方协查!C:C,A8,警方协查!E:E,"GME") -> 5 | F41: =COUNTIFS(KYC调单!C:C,A8,KYC调单!E:E,"QBC")+COUNTIFS(单笔交易!C:C,A8,单笔交易!H:H,"QBC")+COUNTIFS(账户调查!C:C,A8,账户调查!F:F,"QBC")+COUNTIFS(Recall!C:C,A8,Recall!D:D,"QBC")+COUNTIFS(警方协查!C:C,A8,警方协查!E:E,"QBC") -> 0 | G41: =COUNTIFS(KYC调单!C:C,A8,KYC调单!E:E,"Thunes")+COUNTIFS(单笔交易!C:C,A8,单笔交易!H:H,"Thunes")+COUNTIFS(账户调查!C:C,A8,账户调查!F:F,"Thunes")+COUNTIFS(Recall!C:C,A8,Recall!D:D,"Thunes")+COUNTIFS(警方协查!C:C,A8,警方协查!E:E,"Thunes") -> 2 | H41: =COUNTIF(结汇!C:C,A8) -> 2 | I41: =COUNTIFS(KYC调单!C:C,A8,KYC调单!E:E,"平安银行")+COUNTIFS(单笔交易!C:C,A8,单笔交易!H:H,"平安银行")+COUNTIFS(账户调查!C:C,A8,账户调查!F:F,"平安银行")+COUNTIFS(Recall!C:C,A8,Recall!D:D,"平安银行")+COUNTIFS(警方协查!C:C,A8,警方协查!E:E,"平安银行") -> 0 | J41: =COUNTIFS(KYC调单!C:C,A8,KYC调单!E:E,"PING PONG")+COUNTIFS(单笔交易!C:C,A8,单笔交易!H:H,"PING PONG")+COUNTIFS(账户调查!C:C,A8,账户调查!F:F,"PING PONG")+COUNTIFS(Recall!C:C,A8,Recall!D:D,"PING PONG")+COUNTIFS(警方协查!C:C,A8,警方协查!E:E,"PING PONG") -> 0 | K41: =COUNTIFS(单笔交易!C:C,A41,单笔交易!H:H,"SCB")+COUNTIFS(账户调查!C:C,A41,账户调查!F:F,"SCB")+COUNTIFS(Recall!C:C,A41,Recall!D:D,"SCB") -> 0 | L41: =COUNTIFS(单笔交易!C:C,A41,单笔交易!H:H,"Baokim")+COUNTIFS(账户调查!C:C,A41,账户调查!F:F,"Baokim") -> 0 | M41: =COUNTIFS(警方协查!C:C,A41,警方协查!E:E,"其他警方")+COUNTIFS(账户调查!C:C,A41,账户调查!F:F,"Payoneer")+COUNTIFS(账户调查!C:C,A41,账户调查!F:F,"DSGpay")+COUNTIFS(单笔交易!C:C,A41,单笔交易!H:H,"DSGpay")+COUNTIFS(单笔交易!C:C,A41,单笔交易!H:H,"Moolahgo")+COUNTIFS(账户调查!C:C,A41,账户调查!F:F,"Sentbe")+COUNTIFS(账户调查!C:C,A41,账户调查!F:F,"flutterwave")+COUNTIFS(单笔交易!C:C,A41,单笔交易!H:H,"Pyvio")+COUNTIFS(账户调查!C:C,A41,账户调查!F:F,"HPAY") -> 0 | N41: =COUNTIFS(单笔交易!C:C,A41,单笔交易!H:H,"Nium")+COUNTIFS(账户调查!C:C,A41,账户调查!F:F,"Nium")+COUNTIFS(KYC调单!C:C,A8,KYC调单!E:E,"Nium") -> 0 | O41: =COUNTIFS(警方协查!C:C,A41,警方协查!E:E,"OpenPayd")+COUNTIFS(单笔交易!C:C,A41,单笔交易!H:H,"OpenPayd")+COUNTIFS(账户调查!C:C,A41,账户调查!F:F,"OpenPayd")+COUNTIFS(Recall!C:C,A41,Recall!D:D,"OpenPayd") -> 0 | P41: =COUNTIFS(KYC调单!C:C,A8,KYC调单!E:E,"IBC")+COUNTIFS(单笔交易!C:C,A8,单笔交易!H:H,"IBC")+COUNTIFS(账户调查!C:C,A8,账户调查!F:F,"IBC") -> 0 | Q41: =COUNTIFS(KYC调单!C:C,A41,KYC调单!E:E,"TransferMate")+COUNTIFS(单笔交易!C:C,A41,单笔交易!H:H,"TransferMate")+COUNTIFS(账户调查!C:C,A41,账户调查!F:F,"TransferMate") -> 0 | S41: =SUM(B41:R41) -> 75 | T41: =_xlfn.IFS(S41=F8,"一致") -> 一致
A42: 2025年7月 | B42: =COUNTIFS(KYC调单!C:C,A9,KYC调单!E:E,"DBS")+COUNTIFS(单笔交易!C:C,A9,单笔交易!H:H,"DBS")+COUNTIFS(账户调查!C:C,A9,账户调查!F:F,"DBS")+COUNTIFS(Recall!C:C,A9,Recall!D:D,"DBS")+COUNTIFS(警方协查!C:C,A9,警方协查!E:E,"DBS") -> 32 | C42: =COUNTIFS(KYC调单!C:C,A9,KYC调单!E:E,"Banking Circle")+COUNTIFS(单笔交易!C:C,A9,单笔交易!H:H,"Banking Circle")+COUNTIFS(账户调查!C:C,A9,账户调查!F:F,"Banking Circle")+COUNTIFS(Recall!C:C,A9,Recall!D:D,"Banking Circle")+COUNTIFS(警方协查!C:C,A9,警方协查!E:E,"Banking Circle") -> 31 | D42: =COUNTIFS(KYC调单!C:C,A9,KYC调单!E:E,"M-DAQ")+COUNTIFS(单笔交易!C:C,A9,单笔交易!H:H,"M-DAQ")+COUNTIFS(账户调查!C:C,A9,账户调查!F:F,"M-DAQ")+COUNTIFS(Recall!C:C,A9,Recall!D:D,"M-DAQ")+COUNTIFS(警方协查!C:C,A9,警方协查!E:E,"M-DAQ") -> 4 | E42: =COUNTIFS(KYC调单!C:C,A9,KYC调单!E:E,"GME")+COUNTIFS(单笔交易!C:C,A9,单笔交易!H:H,"GME")+COUNTIFS(账户调查!C:C,A9,账户调查!F:F,"GME")+COUNTIFS(Recall!C:C,A9,Recall!D:D,"GME")+COUNTIFS(警方协查!C:C,A9,警方协查!E:E,"GME") -> 5 | F42: =COUNTIFS(KYC调单!C:C,A9,KYC调单!E:E,"QBC")+COUNTIFS(单笔交易!C:C,A9,单笔交易!H:H,"QBC")+COUNTIFS(账户调查!C:C,A9,账户调查!F:F,"QBC")+COUNTIFS(Recall!C:C,A9,Recall!D:D,"QBC")+COUNTIFS(警方协查!C:C,A9,警方协查!E:E,"QBC") -> 0 | G42: =COUNTIFS(KYC调单!C:C,A9,KYC调单!E:E,"Thunes")+COUNTIFS(单笔交易!C:C,A9,单笔交易!H:H,"Thunes")+COUNTIFS(账户调查!C:C,A9,账户调查!F:F,"Thunes")+COUNTIFS(Recall!C:C,A9,Recall!D:D,"Thunes")+COUNTIFS(警方协查!C:C,A9,警方协查!E:E,"Thunes") -> 1 | H42: =COUNTIF(结汇!C:C,A9) -> 2 | I42: =COUNTIFS(KYC调单!C:C,A9,KYC调单!E:E,"平安银行")+COUNTIFS(单笔交易!C:C,A9,单笔交易!H:H,"平安银行")+COUNTIFS(账户调查!C:C,A9,账户调查!F:F,"平安银行")+COUNTIFS(Recall!C:C,A9,Recall!D:D,"平安银行")+COUNTIFS(警方协查!C:C,A9,警方协查!E:E,"平安银行") -> 1 | J42: =COUNTIFS(KYC调单!C:C,A9,KYC调单!E:E,"PING PONG")+COUNTIFS(单笔交易!C:C,A9,单笔交易!H:H,"PING PONG")+COUNTIFS(账户调查!C:C,A9,账户调查!F:F,"PING PONG")+COUNTIFS(Recall!C:C,A9,Recall!D:D,"PING PONG")+COUNTIFS(警方协查!C:C,A9,警方协查!E:E,"PING PONG") -> 1 | K42: =COUNTIFS(单笔交易!C:C,A42,单笔交易!H:H,"SCB")+COUNTIFS(账户调查!C:C,A42,账户调查!F:F,"SCB")+COUNTIFS(Recall!C:C,A42,Recall!D:D,"SCB") -> 5 | L42: =COUNTIFS(单笔交易!C:C,A42,单笔交易!H:H,"Baokim")+COUNTIFS(账户调查!C:C,A42,账户调查!F:F,"Baokim") -> 2 | M42: =COUNTIFS(警方协查!C:C,A42,警方协查!E:E,"其他警方")+COUNTIFS(账户调查!C:C,A42,账户调查!F:F,"Payoneer")+COUNTIFS(账户调查!C:C,A42,账户调查!F:F,"DSGpay")+COUNTIFS(单笔交易!C:C,A42,单笔交易!H:H,"DSGpay")+COUNTIFS(单笔交易!C:C,A42,单笔交易!H:H,"Moolahgo")+COUNTIFS(账户调查!C:C,A42,账户调查!F:F,"Sentbe")+COUNTIFS(账户调查!C:C,A42,账户调查!F:F,"flutterwave")+COUNTIFS(单笔交易!C:C,A42,单笔交易!H:H,"Pyvio")+COUNTIFS(账户调查!C:C,A42,账户调查!F:F,"HPAY") -> 1 | N42: =COUNTIFS(单笔交易!C:C,A42,单笔交易!H:H,"Nium")+COUNTIFS(账户调查!C:C,A42,账户调查!F:F,"Nium")+COUNTIFS(KYC调单!C:C,A9,KYC调单!E:E,"Nium") -> 1 | O42: =COUNTIFS(警方协查!C:C,A42,警方协查!E:E,"OpenPayd")+COUNTIFS(单笔交易!C:C,A42,单笔交易!H:H,"OpenPayd")+COUNTIFS(账户调查!C:C,A42,账户调查!F:F,"OpenPayd")+COUNTIFS(Recall!C:C,A42,Recall!D:D,"OpenPayd") -> 0 | P42: =COUNTIFS(KYC调单!C:C,A9,KYC调单!E:E,"IBC")+COUNTIFS(单笔交易!C:C,A9,单笔交易!H:H,"IBC")+COUNTIFS(账户调查!C:C,A9,账户调查!F:F,"IBC") -> 0 | Q42: =COUNTIFS(KYC调单!C:C,A42,KYC调单!E:E,"TransferMate")+COUNTIFS(单笔交易!C:C,A42,单笔交易!H:H,"TransferMate")+COUNTIFS(账户调查!C:C,A42,账户调查!F:F,"TransferMate") -> 0 | S42: =SUM(B42:R42) -> 86 | T42: =_xlfn.IFS(S42=F9,"一致") -> 一致
A43: 2025年8月 | B43: =COUNTIFS(KYC调单!C:C,A10,KYC调单!E:E,"DBS")+COUNTIFS(单笔交易!C:C,A10,单笔交易!H:H,"DBS")+COUNTIFS(账户调查!C:C,A10,账户调查!F:F,"DBS")+COUNTIFS(Recall!C:C,A10,Recall!D:D,"DBS")+COUNTIFS(警方协查!C:C,A10,警方协查!E:E,"DBS") -> 25 | C43: =COUNTIFS(KYC调单!C:C,A10,KYC调单!E:E,"Banking Circle")+COUNTIFS(单笔交易!C:C,A10,单笔交易!H:H,"Banking Circle")+COUNTIFS(账户调查!C:C,A10,账户调查!F:F,"Banking Circle")+COUNTIFS(Recall!C:C,A10,Recall!D:D,"Banking Circle")+COUNTIFS(警方协查!C:C,A10,警方协查!E:E,"Banking Circle") -> 21 | D43: =COUNTIFS(KYC调单!C:C,A10,KYC调单!E:E,"M-DAQ")+COUNTIFS(单笔交易!C:C,A10,单笔交易!H:H,"M-DAQ")+COUNTIFS(账户调查!C:C,A10,账户调查!F:F,"M-DAQ")+COUNTIFS(Recall!C:C,A10,Recall!D:D,"M-DAQ")+COUNTIFS(警方协查!C:C,A10,警方协查!E:E,"M-DAQ") -> 5 | E43: =COUNTIFS(KYC调单!C:C,A10,KYC调单!E:E,"GME")+COUNTIFS(单笔交易!C:C,A10,单笔交易!H:H,"GME")+COUNTIFS(账户调查!C:C,A10,账户调查!F:F,"GME")+COUNTIFS(Recall!C:C,A10,Recall!D:D,"GME")+COUNTIFS(警方协查!C:C,A10,警方协查!E:E,"GME") -> 2 | F43: =COUNTIFS(KYC调单!C:C,A10,KYC调单!E:E,"QBC")+COUNTIFS(单笔交易!C:C,A10,单笔交易!H:H,"QBC")+COUNTIFS(账户调查!C:C,A10,账户调查!F:F,"QBC")+COUNTIFS(Recall!C:C,A10,Recall!D:D,"QBC")+COUNTIFS(警方协查!C:C,A10,警方协查!E:E,"QBC") -> 0 | G43: =COUNTIFS(KYC调单!C:C,A10,KYC调单!E:E,"Thunes")+COUNTIFS(单笔交易!C:C,A10,单笔交易!H:H,"Thunes")+COUNTIFS(账户调查!C:C,A10,账户调查!F:F,"Thunes")+COUNTIFS(Recall!C:C,A10,Recall!D:D,"Thunes")+COUNTIFS(警方协查!C:C,A10,警方协查!E:E,"Thunes") -> 3 | H43: =COUNTIF(结汇!C:C,A10) -> 1 | I43: =COUNTIFS(KYC调单!C:C,A10,KYC调单!E:E,"平安银行")+COUNTIFS(单笔交易!C:C,A10,单笔交易!H:H,"平安银行")+COUNTIFS(账户调查!C:C,A10,账户调查!F:F,"平安银行")+COUNTIFS(Recall!C:C,A10,Recall!D:D,"平安银行")+COUNTIFS(警方协查!C:C,A10,警方协查!E:E,"平安银行") -> 2 | J43: =COUNTIFS(KYC调单!C:C,A10,KYC调单!E:E,"PING PONG")+COUNTIFS(单笔交易!C:C,A10,单笔交易!H:H,"PING PONG")+COUNTIFS(账户调查!C:C,A10,账户调查!F:F,"PING PONG")+COUNTIFS(Recall!C:C,A10,Recall!D:D,"PING PONG")+COUNTIFS(警方协查!C:C,A10,警方协查!E:E,"PING PONG") -> 0 | K43: =COUNTIFS(单笔交易!C:C,A43,单笔交易!H:H,"SCB")+COUNTIFS(账户调查!C:C,A43,账户调查!F:F,"SCB")+COUNTIFS(Recall!C:C,A43,Recall!D:D,"SCB") -> 7 | L43: =COUNTIFS(单笔交易!C:C,A43,单笔交易!H:H,"Baokim")+COUNTIFS(账户调查!C:C,A43,账户调查!F:F,"Baokim") -> 0 | M43: =COUNTIFS(警方协查!C:C,A43,警方协查!E:E,"其他警方")+COUNTIFS(账户调查!C:C,A43,账户调查!F:F,"Payoneer")+COUNTIFS(账户调查!C:C,A43,账户调查!F:F,"DSGpay")+COUNTIFS(单笔交易!C:C,A43,单笔交易!H:H,"DSGpay")+COUNTIFS(单笔交易!C:C,A43,单笔交易!H:H,"Moolahgo")+COUNTIFS(账户调查!C:C,A43,账户调查!F:F,"Sentbe")+COUNTIFS(账户调查!C:C,A43,账户调查!F:F,"flutterwave")+COUNTIFS(单笔交易!C:C,A43,单笔交易!H:H,"Pyvio")+COUNTIFS(账户调查!C:C,A43,账户调查!F:F,"HPAY") -> 0 | N43: =COUNTIFS(单笔交易!C:C,A43,单笔交易!H:H,"Nium")+COUNTIFS(账户调查!C:C,A43,账户调查!F:F,"Nium")+COUNTIFS(KYC调单!C:C,A10,KYC调单!E:E,"Nium") -> 1 | O43: =COUNTIFS(警方协查!C:C,A43,警方协查!E:E,"OpenPayd")+COUNTIFS(单笔交易!C:C,A43,单笔交易!H:H,"OpenPayd")+COUNTIFS(账户调查!C:C,A43,账户调查!F:F,"OpenPayd")+COUNTIFS(Recall!C:C,A43,Recall!D:D,"OpenPayd") -> 2 | P43: =COUNTIFS(KYC调单!C:C,A10,KYC调单!E:E,"IBC")+COUNTIFS(单笔交易!C:C,A10,单笔交易!H:H,"IBC")+COUNTIFS(账户调查!C:C,A10,账户调查!F:F,"IBC") -> 0 | Q43: =COUNTIFS(KYC调单!C:C,A43,KYC调单!E:E,"TransferMate")+COUNTIFS(单笔交易!C:C,A43,单笔交易!H:H,"TransferMate")+COUNTIFS(账户调查!C:C,A43,账户调查!F:F,"TransferMate") -> 0 | S43: =SUM(B43:R43) -> 69 | T43: =_xlfn.IFS(S43=F10,"一致") -> 一致
A44: 2025年9月 | B44: =COUNTIFS(KYC调单!C:C,A11,KYC调单!E:E,"DBS")+COUNTIFS(单笔交易!C:C,A11,单笔交易!H:H,"DBS")+COUNTIFS(账户调查!C:C,A11,账户调查!F:F,"DBS")+COUNTIFS(Recall!C:C,A11,Recall!D:D,"DBS")+COUNTIFS(警方协查!C:C,A11,警方协查!E:E,"DBS") -> 16 | C44: =COUNTIFS(KYC调单!C:C,A11,KYC调单!E:E,"Banking Circle")+COUNTIFS(单笔交易!C:C,A11,单笔交易!H:H,"Banking Circle")+COUNTIFS(账户调查!C:C,A11,账户调查!F:F,"Banking Circle")+COUNTIFS(Recall!C:C,A11,Recall!D:D,"Banking Circle")+COUNTIFS(警方协查!C:C,A11,警方协查!E:E,"Banking Circle") -> 25 | D44: =COUNTIFS(KYC调单!C:C,A11,KYC调单!E:E,"M-DAQ")+COUNTIFS(单笔交易!C:C,A11,单笔交易!H:H,"M-DAQ")+COUNTIFS(账户调查!C:C,A11,账户调查!F:F,"M-DAQ")+COUNTIFS(Recall!C:C,A11,Recall!D:D,"M-DAQ")+COUNTIFS(警方协查!C:C,A11,警方协查!E:E,"M-DAQ") -> 0 | E44: =COUNTIFS(KYC调单!C:C,A11,KYC调单!E:E,"GME")+COUNTIFS(单笔交易!C:C,A11,单笔交易!H:H,"GME")+COUNTIFS(账户调查!C:C,A11,账户调查!F:F,"GME")+COUNTIFS(Recall!C:C,A11,Recall!D:D,"GME")+COUNTIFS(警方协查!C:C,A11,警方协查!E:E,"GME") -> 6 | F44: =COUNTIFS(KYC调单!C:C,A11,KYC调单!E:E,"QBC")+COUNTIFS(单笔交易!C:C,A11,单笔交易!H:H,"QBC")+COUNTIFS(账户调查!C:C,A11,账户调查!F:F,"QBC")+COUNTIFS(Recall!C:C,A11,Recall!D:D,"QBC")+COUNTIFS(警方协查!C:C,A11,警方协查!E:E,"QBC") -> 1 | G44: =COUNTIFS(KYC调单!C:C,A11,KYC调单!E:E,"Thunes")+COUNTIFS(单笔交易!C:C,A11,单笔交易!H:H,"Thunes")+COUNTIFS(账户调查!C:C,A11,账户调查!F:F,"Thunes")+COUNTIFS(Recall!C:C,A11,Recall!D:D,"Thunes")+COUNTIFS(警方协查!C:C,A11,警方协查!E:E,"Thunes") -> 4 | H44: =COUNTIF(结汇!C:C,A11) -> 2 | I44: =COUNTIFS(KYC调单!C:C,A11,KYC调单!E:E,"平安银行")+COUNTIFS(单笔交易!C:C,A11,单笔交易!H:H,"平安银行")+COUNTIFS(账户调查!C:C,A11,账户调查!F:F,"平安银行")+COUNTIFS(Recall!C:C,A11,Recall!D:D,"平安银行")+COUNTIFS(警方协查!C:C,A11,警方协查!E:E,"平安银行") -> 3 | J44: =COUNTIFS(KYC调单!C:C,A11,KYC调单!E:E,"PING PONG")+COUNTIFS(单笔交易!C:C,A11,单笔交易!H:H,"PING PONG")+COUNTIFS(账户调查!C:C,A11,账户调查!F:F,"PING PONG")+COUNTIFS(Recall!C:C,A11,Recall!D:D,"PING PONG")+COUNTIFS(警方协查!C:C,A11,警方协查!E:E,"PING PONG") -> 0 | K44: =COUNTIFS(单笔交易!C:C,A44,单笔交易!H:H,"SCB")+COUNTIFS(账户调查!C:C,A44,账户调查!F:F,"SCB")+COUNTIFS(Recall!C:C,A44,Recall!D:D,"SCB") -> 15 | L44: =COUNTIFS(单笔交易!C:C,A44,单笔交易!H:H,"Baokim")+COUNTIFS(账户调查!C:C,A44,账户调查!F:F,"Baokim") -> 0 | M44: =COUNTIFS(警方协查!C:C,A44,警方协查!E:E,"其他警方")+COUNTIFS(账户调查!C:C,A44,账户调查!F:F,"Payoneer")+COUNTIFS(账户调查!C:C,A44,账户调查!F:F,"DSGpay")+COUNTIFS(单笔交易!C:C,A44,单笔交易!H:H,"DSGpay")+COUNTIFS(单笔交易!C:C,A44,单笔交易!H:H,"Moolahgo")+COUNTIFS(账户调查!C:C,A44,账户调查!F:F,"Sentbe")+COUNTIFS(账户调查!C:C,A44,账户调查!F:F,"flutterwave")+COUNTIFS(单笔交易!C:C,A44,单笔交易!H:H,"Pyvio")+COUNTIFS(账户调查!C:C,A44,账户调查!F:F,"HPAY") -> 0 | N44: =COUNTIFS(单笔交易!C:C,A44,单笔交易!H:H,"Nium")+COUNTIFS(账户调查!C:C,A44,账户调查!F:F,"Nium")+COUNTIFS(KYC调单!C:C,A11,KYC调单!E:E,"Nium") -> 1 | O44: =COUNTIFS(警方协查!C:C,A44,警方协查!E:E,"OpenPayd")+COUNTIFS(单笔交易!C:C,A44,单笔交易!H:H,"OpenPayd")+COUNTIFS(账户调查!C:C,A44,账户调查!F:F,"OpenPayd")+COUNTIFS(Recall!C:C,A44,Recall!D:D,"OpenPayd") -> 3 | P44: =COUNTIFS(KYC调单!C:C,A11,KYC调单!E:E,"IBC")+COUNTIFS(单笔交易!C:C,A11,单笔交易!H:H,"IBC")+COUNTIFS(账户调查!C:C,A11,账户调查!F:F,"IBC") -> 0 | Q44: =COUNTIFS(KYC调单!C:C,A44,KYC调单!E:E,"TransferMate")+COUNTIFS(单笔交易!C:C,A44,单笔交易!H:H,"TransferMate")+COUNTIFS(账户调查!C:C,A44,账户调查!F:F,"TransferMate") -> 0 | S44: =SUM(B44:R44) -> 76 | T44: =_xlfn.IFS(S44=F11,"一致") -> 一致
A45: 2025年10月 | B45: =COUNTIFS(KYC调单!C:C,A12,KYC调单!E:E,"DBS")+COUNTIFS(单笔交易!C:C,A12,单笔交易!H:H,"DBS")+COUNTIFS(账户调查!C:C,A12,账户调查!F:F,"DBS")+COUNTIFS(Recall!C:C,A12,Recall!D:D,"DBS")+COUNTIFS(警方协查!C:C,A12,警方协查!E:E,"DBS") -> 20 | C45: =COUNTIFS(KYC调单!C:C,A12,KYC调单!E:E,"Banking Circle")+COUNTIFS(单笔交易!C:C,A12,单笔交易!H:H,"Banking Circle")+COUNTIFS(账户调查!C:C,A12,账户调查!F:F,"Banking Circle")+COUNTIFS(Recall!C:C,A12,Recall!D:D,"Banking Circle")+COUNTIFS(警方协查!C:C,A12,警方协查!E:E,"Banking Circle") -> 30 | D45: =COUNTIFS(KYC调单!C:C,A12,KYC调单!E:E,"M-DAQ")+COUNTIFS(单笔交易!C:C,A12,单笔交易!H:H,"M-DAQ")+COUNTIFS(账户调查!C:C,A12,账户调查!F:F,"M-DAQ")+COUNTIFS(Recall!C:C,A12,Recall!D:D,"M-DAQ")+COUNTIFS(警方协查!C:C,A12,警方协查!E:E,"M-DAQ") -> 9 | E45: =COUNTIFS(KYC调单!C:C,A12,KYC调单!E:E,"GME")+COUNTIFS(单笔交易!C:C,A12,单笔交易!H:H,"GME")+COUNTIFS(账户调查!C:C,A12,账户调查!F:F,"GME")+COUNTIFS(Recall!C:C,A12,Recall!D:D,"GME")+COUNTIFS(警方协查!C:C,A12,警方协查!E:E,"GME") -> 3 | F45: =COUNTIFS(KYC调单!C:C,A12,KYC调单!E:E,"QBC")+COUNTIFS(单笔交易!C:C,A12,单笔交易!H:H,"QBC")+COUNTIFS(账户调查!C:C,A12,账户调查!F:F,"QBC")+COUNTIFS(Recall!C:C,A12,Recall!D:D,"QBC")+COUNTIFS(警方协查!C:C,A12,警方协查!E:E,"QBC") -> 0 | G45: =COUNTIFS(KYC调单!C:C,A12,KYC调单!E:E,"Thunes")+COUNTIFS(单笔交易!C:C,A12,单笔交易!H:H,"Thunes")+COUNTIFS(账户调查!C:C,A12,账户调查!F:F,"Thunes")+COUNTIFS(Recall!C:C,A12,Recall!D:D,"Thunes")+COUNTIFS(警方协查!C:C,A12,警方协查!E:E,"Thunes") -> 3 | H45: =COUNTIF(结汇!C:C,A12) -> 1 | I45: =COUNTIFS(KYC调单!C:C,A12,KYC调单!E:E,"平安银行")+COUNTIFS(单笔交易!C:C,A12,单笔交易!H:H,"平安银行")+COUNTIFS(账户调查!C:C,A12,账户调查!F:F,"平安银行")+COUNTIFS(Recall!C:C,A12,Recall!D:D,"平安银行")+COUNTIFS(警方协查!C:C,A12,警方协查!E:E,"平安银行") -> 3 | J45: =COUNTIFS(KYC调单!C:C,A12,KYC调单!E:E,"PING PONG")+COUNTIFS(单笔交易!C:C,A12,单笔交易!H:H,"PING PONG")+COUNTIFS(账户调查!C:C,A12,账户调查!F:F,"PING PONG")+COUNTIFS(Recall!C:C,A12,Recall!D:D,"PING PONG")+COUNTIFS(警方协查!C:C,A12,警方协查!E:E,"PING PONG") -> 0 | K45: =COUNTIFS(单笔交易!C:C,A45,单笔交易!H:H,"SCB")+COUNTIFS(账户调查!C:C,A45,账户调查!F:F,"SCB")+COUNTIFS(Recall!C:C,A45,Recall!D:D,"SCB") -> 7 | L45: =COUNTIFS(单笔交易!C:C,A45,单笔交易!H:H,"Baokim")+COUNTIFS(账户调查!C:C,A45,账户调查!F:F,"Baokim") -> 0 | M45: =COUNTIFS(警方协查!C:C,A45,警方协查!E:E,"其他警方")+COUNTIFS(账户调查!C:C,A45,账户调查!F:F,"Payoneer")+COUNTIFS(账户调查!C:C,A45,账户调查!F:F,"DSGpay")+COUNTIFS(单笔交易!C:C,A45,单笔交易!H:H,"DSGpay")+COUNTIFS(单笔交易!C:C,A45,单笔交易!H:H,"Moolahgo")+COUNTIFS(账户调查!C:C,A45,账户调查!F:F,"Sentbe")+COUNTIFS(账户调查!C:C,A45,账户调查!F:F,"flutterwave")+COUNTIFS(单笔交易!C:C,A45,单笔交易!H:H,"Pyvio")+COUNTIFS(账户调查!C:C,A45,账户调查!F:F,"HPAY") -> 0 | N45: =COUNTIFS(单笔交易!C:C,A45,单笔交易!H:H,"Nium")+COUNTIFS(账户调查!C:C,A45,账户调查!F:F,"Nium")+COUNTIFS(KYC调单!C:C,A12,KYC调单!E:E,"Nium") -> 1 | O45: =COUNTIFS(警方协查!C:C,A45,警方协查!E:E,"OpenPayd")+COUNTIFS(单笔交易!C:C,A45,单笔交易!H:H,"OpenPayd")+COUNTIFS(账户调查!C:C,A45,账户调查!F:F,"OpenPayd")+COUNTIFS(Recall!C:C,A45,Recall!D:D,"OpenPayd") -> 6 | P45: =COUNTIFS(KYC调单!C:C,A12,KYC调单!E:E,"IBC")+COUNTIFS(单笔交易!C:C,A12,单笔交易!H:H,"IBC")+COUNTIFS(账户调查!C:C,A12,账户调查!F:F,"IBC") -> 0 | Q45: =COUNTIFS(KYC调单!C:C,A45,KYC调单!E:E,"TransferMate")+COUNTIFS(单笔交易!C:C,A45,单笔交易!H:H,"TransferMate")+COUNTIFS(账户调查!C:C,A45,账户调查!F:F,"TransferMate") -> 0 | S45: =SUM(B45:R45) -> 83 | T45: =_xlfn.IFS(S45=F12,"一致") -> 一致
A46: 2025年11月 | B46: =COUNTIFS(KYC调单!C:C,A13,KYC调单!E:E,"DBS")+COUNTIFS(单笔交易!C:C,A13,单笔交易!H:H,"DBS")+COUNTIFS(账户调查!C:C,A13,账户调查!F:F,"DBS")+COUNTIFS(Recall!C:C,A13,Recall!D:D,"DBS")+COUNTIFS(警方协查!C:C,A13,警方协查!E:E,"DBS") -> 15 | C46: =COUNTIFS(KYC调单!C:C,A13,KYC调单!E:E,"Banking Circle")+COUNTIFS(单笔交易!C:C,A13,单笔交易!H:H,"Banking Circle")+COUNTIFS(账户调查!C:C,A13,账户调查!F:F,"Banking Circle")+COUNTIFS(Recall!C:C,A13,Recall!D:D,"Banking Circle")+COUNTIFS(警方协查!C:C,A13,警方协查!E:E,"Banking Circle") -> 37 | D46: =COUNTIFS(KYC调单!C:C,A13,KYC调单!E:E,"M-DAQ")+COUNTIFS(单笔交易!C:C,A13,单笔交易!H:H,"M-DAQ")+COUNTIFS(账户调查!C:C,A13,账户调查!F:F,"M-DAQ")+COUNTIFS(Recall!C:C,A13,Recall!D:D,"M-DAQ")+COUNTIFS(警方协查!C:C,A13,警方协查!E:E,"M-DAQ") -> 6 | E46: =COUNTIFS(KYC调单!C:C,A13,KYC调单!E:E,"GME")+COUNTIFS(单笔交易!C:C,A13,单笔交易!H:H,"GME")+COUNTIFS(账户调查!C:C,A13,账户调查!F:F,"GME")+COUNTIFS(Recall!C:C,A13,Recall!D:D,"GME")+COUNTIFS(警方协查!C:C,A13,警方协查!E:E,"GME") -> 1 | F46: =COUNTIFS(KYC调单!C:C,A13,KYC调单!E:E,"QBC")+COUNTIFS(单笔交易!C:C,A13,单笔交易!H:H,"QBC")+COUNTIFS(账户调查!C:C,A13,账户调查!F:F,"QBC")+COUNTIFS(Recall!C:C,A13,Recall!D:D,"QBC")+COUNTIFS(警方协查!C:C,A13,警方协查!E:E,"QBC") -> 1 | G46: =COUNTIFS(KYC调单!C:C,A13,KYC调单!E:E,"Thunes")+COUNTIFS(单笔交易!C:C,A13,单笔交易!H:H,"Thunes")+COUNTIFS(账户调查!C:C,A13,账户调查!F:F,"Thunes")+COUNTIFS(Recall!C:C,A13,Recall!D:D,"Thunes")+COUNTIFS(警方协查!C:C,A13,警方协查!E:E,"Thunes") -> 3 | H46: =COUNTIF(结汇!C:C,A13) -> 1 | I46: =COUNTIFS(KYC调单!C:C,A13,KYC调单!E:E,"平安银行")+COUNTIFS(单笔交易!C:C,A13,单笔交易!H:H,"平安银行")+COUNTIFS(账户调查!C:C,A13,账户调查!F:F,"平安银行")+COUNTIFS(Recall!C:C,A13,Recall!D:D,"平安银行")+COUNTIFS(警方协查!C:C,A13,警方协查!E:E,"平安银行") -> 2 | J46: =COUNTIFS(KYC调单!C:C,A13,KYC调单!E:E,"PING PONG")+COUNTIFS(单笔交易!C:C,A13,单笔交易!H:H,"PING PONG")+COUNTIFS(账户调查!C:C,A13,账户调查!F:F,"PING PONG")+COUNTIFS(Recall!C:C,A13,Recall!D:D,"PING PONG")+COUNTIFS(警方协查!C:C,A13,警方协查!E:E,"PING PONG") -> 0 | K46: =COUNTIFS(单笔交易!C:C,A46,单笔交易!H:H,"SCB")+COUNTIFS(账户调查!C:C,A46,账户调查!F:F,"SCB")+COUNTIFS(Recall!C:C,A46,Recall!D:D,"SCB") -> 7 | L46: =COUNTIFS(单笔交易!C:C,A46,单笔交易!H:H,"Baokim")+COUNTIFS(账户调查!C:C,A46,账户调查!F:F,"Baokim") -> 0 | M46: =COUNTIFS(警方协查!C:C,A46,警方协查!E:E,"其他警方")+COUNTIFS(账户调查!C:C,A46,账户调查!F:F,"Payoneer")+COUNTIFS(账户调查!C:C,A46,账户调查!F:F,"DSGpay")+COUNTIFS(单笔交易!C:C,A46,单笔交易!H:H,"DSGpay")+COUNTIFS(单笔交易!C:C,A46,单笔交易!H:H,"Moolahgo")+COUNTIFS(账户调查!C:C,A46,账户调查!F:F,"Sentbe")+COUNTIFS(账户调查!C:C,A46,账户调查!F:F,"flutterwave")+COUNTIFS(单笔交易!C:C,A46,单笔交易!H:H,"Pyvio")+COUNTIFS(账户调查!C:C,A46,账户调查!F:F,"HPAY") -> 2 | N46: =COUNTIFS(单笔交易!C:C,A46,单笔交易!H:H,"Nium")+COUNTIFS(账户调查!C:C,A46,账户调查!F:F,"Nium")+COUNTIFS(KYC调单!C:C,A13,KYC调单!E:E,"Nium") -> 8 | O46: =COUNTIFS(警方协查!C:C,A46,警方协查!E:E,"OpenPayd")+COUNTIFS(单笔交易!C:C,A46,单笔交易!H:H,"OpenPayd")+COUNTIFS(账户调查!C:C,A46,账户调查!F:F,"OpenPayd")+COUNTIFS(Recall!C:C,A46,Recall!D:D,"OpenPayd") -> 9 | P46: =COUNTIFS(KYC调单!C:C,A13,KYC调单!E:E,"IBC")+COUNTIFS(单笔交易!C:C,A13,单笔交易!H:H,"IBC")+COUNTIFS(账户调查!C:C,A13,账户调查!F:F,"IBC") -> 0 | Q46: =COUNTIFS(KYC调单!C:C,A46,KYC调单!E:E,"TransferMate")+COUNTIFS(单笔交易!C:C,A46,单笔交易!H:H,"TransferMate")+COUNTIFS(账户调查!C:C,A46,账户调查!F:F,"TransferMate") -> 0 | S46: =SUM(B46:R46) -> 92 | T46: =_xlfn.IFS(S46=F13,"一致") -> 一致
A47: 2025年12月 | B47: =COUNTIFS(KYC调单!C:C,A14,KYC调单!E:E,"DBS")+COUNTIFS(单笔交易!C:C,A14,单笔交易!H:H,"DBS")+COUNTIFS(账户调查!C:C,A14,账户调查!F:F,"DBS")+COUNTIFS(Recall!C:C,A14,Recall!D:D,"DBS")+COUNTIFS(警方协查!C:C,A14,警方协查!E:E,"DBS") -> 26 | C47: =COUNTIFS(KYC调单!C:C,A14,KYC调单!E:E,"Banking Circle")+COUNTIFS(单笔交易!C:C,A14,单笔交易!H:H,"Banking Circle")+COUNTIFS(账户调查!C:C,A14,账户调查!F:F,"Banking Circle")+COUNTIFS(Recall!C:C,A14,Recall!D:D,"Banking Circle")+COUNTIFS(警方协查!C:C,A14,警方协查!E:E,"Banking Circle") -> 57 | D47: =COUNTIFS(KYC调单!C:C,A14,KYC调单!E:E,"M-DAQ")+COUNTIFS(单笔交易!C:C,A14,单笔交易!H:H,"M-DAQ")+COUNTIFS(账户调查!C:C,A14,账户调查!F:F,"M-DAQ")+COUNTIFS(Recall!C:C,A14,Recall!D:D,"M-DAQ")+COUNTIFS(警方协查!C:C,A14,警方协查!E:E,"M-DAQ") -> 2 | E47: =COUNTIFS(KYC调单!C:C,A14,KYC调单!E:E,"GME")+COUNTIFS(单笔交易!C:C,A14,单笔交易!H:H,"GME")+COUNTIFS(账户调查!C:C,A14,账户调查!F:F,"GME")+COUNTIFS(Recall!C:C,A14,Recall!D:D,"GME")+COUNTIFS(警方协查!C:C,A14,警方协查!E:E,"GME") -> 0 | F47: =COUNTIFS(KYC调单!C:C,A14,KYC调单!E:E,"QBC")+COUNTIFS(单笔交易!C:C,A14,单笔交易!H:H,"QBC")+COUNTIFS(账户调查!C:C,A14,账户调查!F:F,"QBC")+COUNTIFS(Recall!C:C,A14,Recall!D:D,"QBC")+COUNTIFS(警方协查!C:C,A14,警方协查!E:E,"QBC") -> 0 | G47: =COUNTIFS(KYC调单!C:C,A14,KYC调单!E:E,"Thunes")+COUNTIFS(单笔交易!C:C,A14,单笔交易!H:H,"Thunes")+COUNTIFS(账户调查!C:C,A14,账户调查!F:F,"Thunes")+COUNTIFS(Recall!C:C,A14,Recall!D:D,"Thunes")+COUNTIFS(警方协查!C:C,A14,警方协查!E:E,"Thunes") -> 5 | H47: =COUNTIF(结汇!C:C,A14) -> 1 | I47: =COUNTIFS(KYC调单!C:C,A14,KYC调单!E:E,"平安银行")+COUNTIFS(单笔交易!C:C,A14,单笔交易!H:H,"平安银行")+COUNTIFS(账户调查!C:C,A14,账户调查!F:F,"平安银行")+COUNTIFS(Recall!C:C,A14,Recall!D:D,"平安银行")+COUNTIFS(警方协查!C:C,A14,警方协查!E:E,"平安银行") -> 0 | J47: =COUNTIFS(KYC调单!C:C,A14,KYC调单!E:E,"PING PONG")+COUNTIFS(单笔交易!C:C,A14,单笔交易!H:H,"PING PONG")+COUNTIFS(账户调查!C:C,A14,账户调查!F:F,"PING PONG")+COUNTIFS(Recall!C:C,A14,Recall!D:D,"PING PONG")+COUNTIFS(警方协查!C:C,A14,警方协查!E:E,"PING PONG") -> 3 | K47: =COUNTIFS(单笔交易!C:C,A47,单笔交易!H:H,"SCB")+COUNTIFS(账户调查!C:C,A47,账户调查!F:F,"SCB")+COUNTIFS(Recall!C:C,A47,Recall!D:D,"SCB") -> 8 | L47: =COUNTIFS(单笔交易!C:C,A47,单笔交易!H:H,"Baokim")+COUNTIFS(账户调查!C:C,A47,账户调查!F:F,"Baokim") -> 0 | M47: =COUNTIFS(警方协查!C:C,A47,警方协查!E:E,"其他警方")+COUNTIFS(账户调查!C:C,A47,账户调查!F:F,"Payoneer")+COUNTIFS(账户调查!C:C,A47,账户调查!F:F,"DSGpay")+COUNTIFS(单笔交易!C:C,A47,单笔交易!H:H,"DSGpay")+COUNTIFS(单笔交易!C:C,A47,单笔交易!H:H,"Moolahgo")+COUNTIFS(账户调查!C:C,A47,账户调查!F:F,"Sentbe")+COUNTIFS(账户调查!C:C,A47,账户调查!F:F,"flutterwave")+COUNTIFS(单笔交易!C:C,A47,单笔交易!H:H,"Pyvio")+COUNTIFS(账户调查!C:C,A47,账户调查!F:F,"HPAY") -> 5 | N47: =COUNTIFS(单笔交易!C:C,A47,单笔交易!H:H,"Nium")+COUNTIFS(账户调查!C:C,A47,账户调查!F:F,"Nium")+COUNTIFS(KYC调单!C:C,A14,KYC调单!E:E,"Nium") -> 2 | O47: =COUNTIFS(警方协查!C:C,A47,警方协查!E:E,"OpenPayd")+COUNTIFS(单笔交易!C:C,A47,单笔交易!H:H,"OpenPayd")+COUNTIFS(账户调查!C:C,A47,账户调查!F:F,"OpenPayd")+COUNTIFS(Recall!C:C,A47,Recall!D:D,"OpenPayd") -> 9 | P47: =COUNTIFS(KYC调单!C:C,A14,KYC调单!E:E,"IBC")+COUNTIFS(单笔交易!C:C,A14,单笔交易!H:H,"IBC")+COUNTIFS(账户调查!C:C,A14,账户调查!F:F,"IBC") -> 0 | Q47: =COUNTIFS(KYC调单!C:C,A47,KYC调单!E:E,"TransferMate")+COUNTIFS(单笔交易!C:C,A47,单笔交易!H:H,"TransferMate")+COUNTIFS(账户调查!C:C,A47,账户调查!F:F,"TransferMate") -> 0 | S47: =SUM(B47:R47) -> 118 | T47: =_xlfn.IFS(S47=F14,"一致") -> 一致
... A52: 2026年5月 | B52: =COUNTIFS(KYC调单!C:C,A19,KYC调单!E:E,"DBS")+COUNTIFS(单笔交易!C:C,A19,单笔交易!H:H,"DBS")+COUNTIFS(账户调查!C:C,A19,账户调查!F:F,"DBS")+COUNTIFS(Recall!C:C,A19,Recall!D:D,"DBS")+COUNTIFS(警方协查!C:C,A19,警方协查!E:E,"DBS") -> 16 | C52: =COUNTIFS(KYC调单!C:C,A19,KYC调单!E:E,"Banking Circle")+COUNTIFS(单笔交易!C:C,A19,单笔交易!H:H,"Banking Circle")+COUNTIFS(账户调查!C:C,A19,账户调查!F:F,"Banking Circle")+COUNTIFS(Recall!C:C,A19,Recall!D:D,"Banking Circle")+COUNTIFS(警方协查!C:C,A19,警方协查!E:E,"Banking Circle") -> 45 | D52: =COUNTIFS(KYC调单!C:C,A19,KYC调单!E:E,"M-DAQ")+COUNTIFS(单笔交易!C:C,A19,单笔交易!H:H,"M-DAQ")+COUNTIFS(账户调查!C:C,A19,账户调查!F:F,"M-DAQ")+COUNTIFS(Recall!C:C,A19,Recall!D:D,"M-DAQ")+COUNTIFS(警方协查!C:C,A19,警方协查!E:E,"M-DAQ") -> 0 | E52: =COUNTIFS(KYC调单!C:C,A19,KYC调单!E:E,"GME")+COUNTIFS(单笔交易!C:C,A19,单笔交易!H:H,"GME")+COUNTIFS(账户调查!C:C,A19,账户调查!F:F,"GME")+COUNTIFS(Recall!C:C,A19,Recall!D:D,"GME")+COUNTIFS(警方协查!C:C,A19,警方协查!E:E,"GME") -> 9 | F52: =COUNTIFS(KYC调单!C:C,A19,KYC调单!E:E,"QBC")+COUNTIFS(单笔交易!C:C,A19,单笔交易!H:H,"QBC")+COUNTIFS(账户调查!C:C,A19,账户调查!F:F,"QBC")+COUNTIFS(Recall!C:C,A19,Recall!D:D,"QBC")+COUNTIFS(警方协查!C:C,A19,警方协查!E:E,"QBC") -> 1 | G52: =COUNTIFS(KYC调单!C:C,A19,KYC调单!E:E,"Thunes")+COUNTIFS(单笔交易!C:C,A19,单笔交易!H:H,"Thunes")+COUNTIFS(账户调查!C:C,A19,账户调查!F:F,"Thunes")+COUNTIFS(Recall!C:C,A19,Recall!D:D,"Thunes")+COUNTIFS(警方协查!C:C,A19,警方协查!E:E,"Thunes") -> 4 | H52: =COUNTIF(结汇!C:C,A19) -> 2 | I52: =COUNTIFS(KYC调单!C:C,A19,KYC调单!E:E,"平安银行")+COUNTIFS(单笔交易!C:C,A19,单笔交易!H:H,"平安银行")+COUNTIFS(账户调查!C:C,A19,账户调查!F:F,"平安银行")+COUNTIFS(Recall!C:C,A19,Recall!D:D,"平安银行")+COUNTIFS(警方协查!C:C,A19,警方协查!E:E,"平安银行") -> 2 | J52: =COUNTIFS(KYC调单!C:C,A19,KYC调单!E:E,"PING PONG")+COUNTIFS(单笔交易!C:C,A19,单笔交易!H:H,"PING PONG")+COUNTIFS(账户调查!C:C,A19,账户调查!F:F,"PING PONG")+COUNTIFS(Recall!C:C,A19,Recall!D:D,"PING PONG")+COUNTIFS(警方协查!C:C,A19,警方协查!E:E,"PING PONG") -> 1 | K52: =COUNTIFS(单笔交易!C:C,A52,单笔交易!H:H,"SCB")+COUNTIFS(账户调查!C:C,A52,账户调查!F:F,"SCB")+COUNTIFS(Recall!C:C,A52,Recall!D:D,"SCB") -> 28 | L52: =COUNTIFS(单笔交易!C:C,A52,单笔交易!H:H,"Baokim")+COUNTIFS(账户调查!C:C,A52,账户调查!F:F,"Baokim") -> 0 | M52: =COUNTIFS(警方协查!C:C,A52,警方协查!E:E,"其他警方")+COUNTIFS(账户调查!C:C,A52,账户调查!F:F,"Payoneer")+COUNTIFS(账户调查!C:C,A52,账户调查!F:F,"DSGpay")+COUNTIFS(单笔交易!C:C,A52,单笔交易!H:H,"DSGpay")+COUNTIFS(单笔交易!C:C,A52,单笔交易!H:H,"Moolahgo")+COUNTIFS(账户调查!C:C,A52,账户调查!F:F,"Sentbe")+COUNTIFS(账户调查!C:C,A52,账户调查!F:F,"flutterwave")+COUNTIFS(单笔交易!C:C,A52,单笔交易!H:H,"Pyvio")+COUNTIFS(账户调查!C:C,A52,账户调查!F:F,"HPAY") -> 6 | N52: =COUNTIFS(单笔交易!C:C,A52,单笔交易!H:H,"Nium")+COUNTIFS(账户调查!C:C,A52,账户调查!F:F,"Nium")+COUNTIFS(KYC调单!C:C,A19,KYC调单!E:E,"Nium") -> 1 | O52: =COUNTIFS(警方协查!C:C,A52,警方协查!E:E,"OpenPayd")+COUNTIFS(单笔交易!C:C,A52,单笔交易!H:H,"OpenPayd")+COUNTIFS(账户调查!C:C,A52,账户调查!F:F,"OpenPayd")+COUNTIFS(Recall!C:C,A52,Recall!D:D,"OpenPayd") -> 7 | P52: =COUNTIFS(KYC调单!C:C,A19,KYC调单!E:E,"IBC")+COUNTIFS(单笔交易!C:C,A19,单笔交易!H:H,"IBC")+COUNTIFS(账户调查!C:C,A19,账户调查!F:F,"IBC") -> 8 | Q52: =COUNTIFS(KYC调单!C:C,A52,KYC调单!E:E,"TransferMate")+COUNTIFS(单笔交易!C:C,A52,单笔交易!H:H,"TransferMate")+COUNTIFS(账户调查!C:C,A52,账户调查!F:F,"TransferMate") -> 6 | S52: =SUM(B52:R52) -> 136 | T52: =_xlfn.IFS(S52=F19,"一致") -> #N/A
A53: 2026年6月 | B53: =COUNTIFS(KYC调单!C:C,A20,KYC调单!E:E,"DBS")+COUNTIFS(单笔交易!C:C,A20,单笔交易!H:H,"DBS")+COUNTIFS(账户调查!C:C,A20,账户调查!F:F,"DBS")+COUNTIFS(Recall!C:C,A20,Recall!D:D,"DBS")+COUNTIFS(警方协查!C:C,A20,警方协查!E:E,"DBS") -> 23 | C53: =COUNTIFS(KYC调单!C:C,A20,KYC调单!E:E,"Banking Circle")+COUNTIFS(单笔交易!C:C,A20,单笔交易!H:H,"Banking Circle")+COUNTIFS(账户调查!C:C,A20,账户调查!F:F,"Banking Circle")+COUNTIFS(Recall!C:C,A20,Recall!D:D,"Banking Circle")+COUNTIFS(警方协查!C:C,A20,警方协查!E:E,"Banking Circle") -> 21 | D53: =COUNTIFS(KYC调单!C:C,A20,KYC调单!E:E,"M-DAQ")+COUNTIFS(单笔交易!C:C,A20,单笔交易!H:H,"M-DAQ")+COUNTIFS(账户调查!C:C,A20,账户调查!F:F,"M-DAQ")+COUNTIFS(Recall!C:C,A20,Recall!D:D,"M-DAQ")+COUNTIFS(警方协查!C:C,A20,警方协查!E:E,"M-DAQ") -> 0 | E53: =COUNTIFS(KYC调单!C:C,A20,KYC调单!E:E,"GME")+COUNTIFS(单笔交易!C:C,A20,单笔交易!H:H,"GME")+COUNTIFS(账户调查!C:C,A20,账户调查!F:F,"GME")+COUNTIFS(Recall!C:C,A20,Recall!D:D,"GME")+COUNTIFS(警方协查!C:C,A20,警方协查!E:E,"GME") -> 11 | F53: =COUNTIFS(KYC调单!C:C,A20,KYC调单!E:E,"QBC")+COUNTIFS(单笔交易!C:C,A20,单笔交易!H:H,"QBC")+COUNTIFS(账户调查!C:C,A20,账户调查!F:F,"QBC")+COUNTIFS(Recall!C:C,A20,Recall!D:D,"QBC")+COUNTIFS(警方协查!C:C,A20,警方协查!E:E,"QBC") -> 0 | G53: =COUNTIFS(KYC调单!C:C,A20,KYC调单!E:E,"Thunes")+COUNTIFS(单笔交易!C:C,A20,单笔交易!H:H,"Thunes")+COUNTIFS(账户调查!C:C,A20,账户调查!F:F,"Thunes")+COUNTIFS(Recall!C:C,A20,Recall!D:D,"Thunes")+COUNTIFS(警方协查!C:C,A20,警方协查!E:E,"Thunes") -> 6 | H53: =COUNTIF(结汇!C:C,A20) -> 2 | I53: =COUNTIFS(KYC调单!C:C,A20,KYC调单!E:E,"平安银行")+COUNTIFS(单笔交易!C:C,A20,单笔交易!H:H,"平安银行")+COUNTIFS(账户调查!C:C,A20,账户调查!F:F,"平安银行")+COUNTIFS(Recall!C:C,A20,Recall!D:D,"平安银行")+COUNTIFS(警方协查!C:C,A20,警方协查!E:E,"平安银行") -> 1 | J53: =COUNTIFS(KYC调单!C:C,A20,KYC调单!E:E,"PING PONG")+COUNTIFS(单笔交易!C:C,A20,单笔交易!H:H,"PING PONG")+COUNTIFS(账户调查!C:C,A20,账户调查!F:F,"PING PONG")+COUNTIFS(Recall!C:C,A20,Recall!D:D,"PING PONG")+COUNTIFS(警方协查!C:C,A20,警方协查!E:E,"PING PONG") -> 0 | K53: =COUNTIFS(单笔交易!C:C,A53,单笔交易!H:H,"SCB")+COUNTIFS(账户调查!C:C,A53,账户调查!F:F,"SCB")+COUNTIFS(Recall!C:C,A53,Recall!D:D,"SCB") -> 10 | L53: =COUNTIFS(单笔交易!C:C,A53,单笔交易!H:H,"Baokim")+COUNTIFS(账户调查!C:C,A53,账户调查!F:F,"Baokim") -> 0 | M53: =COUNTIFS(警方协查!C:C,A53,警方协查!E:E,"其他警方")+COUNTIFS(账户调查!C:C,A53,账户调查!F:F,"Payoneer")+COUNTIFS(账户调查!C:C,A53,账户调查!F:F,"DSGpay")+COUNTIFS(单笔交易!C:C,A53,单笔交易!H:H,"DSGpay")+COUNTIFS(单笔交易!C:C,A53,单笔交易!H:H,"Moolahgo")+COUNTIFS(账户调查!C:C,A53,账户调查!F:F,"Sentbe")+COUNTIFS(账户调查!C:C,A53,账户调查!F:F,"flutterwave")+COUNTIFS(单笔交易!C:C,A53,单笔交易!H:H,"Pyvio")+COUNTIFS(账户调查!C:C,A53,账户调查!F:F,"HPAY") -> 6 | N53: =COUNTIFS(单笔交易!C:C,A53,单笔交易!H:H,"Nium")+COUNTIFS(账户调查!C:C,A53,账户调查!F:F,"Nium") -> 1 | O53: =COUNTIFS(警方协查!C:C,A53,警方协查!E:E,"OpenPayd")+COUNTIFS(单笔交易!C:C,A53,单笔交易!H:H,"OpenPayd")+COUNTIFS(账户调查!C:C,A53,账户调查!F:F,"OpenPayd")+COUNTIFS(Recall!C:C,A53,Recall!D:D,"OpenPayd") -> 20 | P53: =COUNTIFS(KYC调单!C:C,A20,KYC调单!E:E,"IBC")+COUNTIFS(单笔交易!C:C,A20,单笔交易!H:H,"IBC")+COUNTIFS(账户调查!C:C,A20,账户调查!F:F,"IBC") -> 3 | Q53: =COUNTIFS(KYC调单!C:C,A53,KYC调单!E:E,"TransferMate")+COUNTIFS(单笔交易!C:C,A53,单笔交易!H:H,"TransferMate")+COUNTIFS(账户调查!C:C,A53,账户调查!F:F,"TransferMate") -> 2 | S53: =SUM(B53:R53) -> 106 | T53: =_xlfn.IFS(S53=F20,"一致") -> 一致
